File: data/XRD/data/Dolomite_100.xrdml
<?xml version="1.0" encoding="UTF-8"?>
<xrdMeasurements xmlns="http://www.xrdml.com/XRDMeasurement/1.0" xmlns:xsi="http://www.w3.org/2001/XMLSchema-instance" xsi:schemaLocation="http://www.xrdml.com/XRDMeasurement/1.0 http://www.xrdml.com/XRDMeasurement/1.0/XRDMeasurement.xsd" status="Completed"><sample type="To be analyzed"><id></id></sample><xrdMeasurement status="Completed" measurementType="Scan"><usedWavelength intended="K-Alpha 1"><kAlpha1 unit="Angstrom">1.5405980</kAlpha1><kAlpha2 unit="Angstrom">1.5444260</kAlpha2><kBeta unit="Angstrom">1.3922500</kBeta><ratioKAlpha2KAlpha1>0.5000</ratioKAlpha2KAlpha1></usedWavelength><incidentBeamPath><radius unit="mm">240.00</radius><xRayTube id="1010041" name="PW3373/00 Cu LFF DK184033"><tension unit="kV">45</tension><current unit="mA">40</current><anodeMaterial>Cu</anodeMaterial><focus type="Line"><length unit="mm">12.0</length><width unit="mm">0.4</width><takeOffAngle unit="deg">6.0</takeOffAngle></focus></xRayTube><sollerSlit id="21010002" name="Soller 0.04 rad."><opening unit="rad">0.0400</opening></sollerSlit><mask id="22080002" name="Inc. Mask Fixed  10 mm (MPD/MRD)"><width unit="mm">6.60</width></mask><antiScatterSlit id="22010003" name="Slit Fixed 1°" xsi:type="fixedAntiScatterSlitType"><height unit="mm">1.52</height></antiScatterSlit><divergenceSlit id="22010004" name="Slit Fixed 1/2°" xsi:type="fixedDivergenceSlitType"><height unit="mm">0.76</height></divergenceSlit></incidentBeamPath><beamKnife id="29010002" name="Beam Knife for X'Celerator"/><diffractedBeamPath><radius unit="mm">240.00</radius><sollerSlit id="21010002" name="Soller 0.04 rad."><opening unit="rad">0.0400</opening></sollerSlit><filter id="20010004" name="Nickel"><material>Ni</material><thickness unit="mm">0.020</thickness></filter><detector id="7010013" name="X'Celerator" xsi:type="rtmsDetectorType"><mode>Scanning</mode><activeLength unit="deg">2.122</activeLength></detector></diffractedBeamPath><scan appendNumber="0" status="Completed" mode="Continuous" scanAxis="Gonio"><header><startTimeStamp>2009-08-03T11:39:18</startTimeStamp><endTimeStamp>2009-08-03T11:50:56</endTimeStamp><author><name>Administrator</name></author><source><applicationSoftware version="2.0">X'Pert Data Collector</applicationSoftware><instrumentControlSoftware version="1.5 ">XPERT-PRO</instrumentControlSoftware><instrumentID>0000000013030094</instrumentID></source></header><dataPoints><positions axis="2Theta" unit="deg"><startPosition>5.00417782</startPosition><endPosition>74.99932830</endPosition></positions><positions axis="Omega" unit="deg"><startPosition>2.50208891</startPosition><endPosition>37.49966415</endPosition></positions><commonCountingTime unit="seconds">10.160</commonCountingTime><intensities unit="counts">556 576 566 586 568 595 558 579 599 608 598 599 593 553 596 576 576 587 574 605 576 555 585 577 592 553 574 570 586 602 561 586 533 611 551 577 556 602 601 576 632 582 536 546 525 519 537 538 579 540 548 591 554 551 501 530 520 502 535 580 558 555 577 544 543 554 577 579 545 539 565 517 569 526 557 584 540 518 502 498 520 527 608 530 528 534 537 534 522 528 536 532 529 536 486 519 471 513 476 488 486 507 526 578 551 435 517 499 493 473 498 523 548 514 547 517 467 488 484 532 540 527 517 529 459 484 459 499 496 515 502 550 534 502 483 472 494 499 493 444 485 467 495 457 488 505 488 474 474 467 456 455 504 472 524 537 484 453 433 512 536 459 439 473 507 492 454 451 473 455 440 477 502 497 473 468 462 456 435 465 462 490 481 515 441 451 444 460 430 461 441 459 439 475 435 429 455 446 451 475 450 459 447 455 446 459 431 433 453 453 443 453 444 425 440 429 415 399 472 413 452 462 434 410 432 421 432 434 429 476 416 395 443 425 463 407 431 452 391 450 455 390 401 409 400 418 403 416 435 398 449 378 425 399 422 428 412 390 435 412 425 430 394 407 414 395 386 429 362 422 409 435 398 412 400 390 379 393 371 359 404 420 404 362 399 388 395 367 395 422 389 361 390 378 405 371 386 347 368 372 352 376 402 400 391 384 395 383 418 383 387 372 358 392 382 380 367 395 379 372 373 353 377 381 356 368 356 414 371 351 363 386 345 334 343 365 366 372 367 376 367 368 366 365 374 351 347 342 316 351 358 355 353 382 341 374 343 351 352 347 317 343 342 350 361 351 341 332 319 356 360 359 350 315 328 363 377 360 377 338 325 349 332 349 337 353 358 299 368 335 325 303 332 334 325 350 306 376 353 343 317 331 352 313 356 341 330 338 335 310 327 320 310 345 319 340 334 337 347 317 342 338 279 359 337 308 331 319 319 335 324 349 278 298 295 299 308 286 316 316 309 264 331 296 304 254 307 319 311 295 279 308 295 287 315 294 298 288 282 293 264 296 292 282 311 311 269 270 308 311 295 294 290 298 316 265 304 297 289 280 307 306 275 292 290 266 296 295 263 287 289 246 268 274 300 313 269 283 274 267 275 295 270 262 257 261 285 278 283 275 275 277 273 278 267 245 267 270 280 235 277 285 258 280 259 269 292 252 258 276 255 232 258 265 230 238 258 226 274 248 247 268 268 245 274 287 259 232 238 237 254 280 268 247 237 251 235 286 258 255 272 249 259 253 247 232 243 245 270 262 253 213 245 232 220 220 242 225 213 236 213 238 215 244 242 269 251 261 202 249 245 232 242 247 202 240 226 226 235 243 235 251 234 233 233 213 202 206 216 232 243 234 209 246 221 236 233 256 232 236 221 245 211 231 235 219 236 205 243 261 215 223 201 228 225 211 231 246 207 246 214 212 222 213 234 241 222 175 233 215 220 211 210 222 196 203 205 199 223 202 207 232 212 227 211 233 195 225 207 255 185 235 231 202 227 226 197 199 233 210 216 202 188 269 213 203 217 201 233 204 199 174 232 237 195 201 204 211 206 221 209 223 217 221 233 189 242 220 207 219 184 206 206 200 210 188 225 193 217 191 227 196 219 216 175 196 212 181 227 193 194 179 194 192 192 211 224 210 199 204 200 159 193 192 194 203 207 186 179 180 188 192 188 181 195 182 193 170 195 180 165 186 189 210 195 234 212 219 199 200 191 192 191 190 190 185 199 183 188 205 214 214 146 167 194 195 201 190 194 159 159 167 200 182 171 197 189 189 209 193 192 200 192 186 180 189 192 203 193 176 194 155 195 192 186 196 183 181 175 165 171 154 152 199 164 200 155 206 188 189 190 172 161 168 168 180 173 148 180 175 178 167 158 202 165 179 178 176 162 170 184 180 183 160 203 168 161 199 191 182 158 158 167 185 169 185 191 159 185 181 185 190 170 164 169 157 163 161 158 171 163 171 197 203 168 164 169 188 182 161 206 171 176 165 154 194 170 169 172 182 171 184 171 188 193 180 174 181 182 192 149 172 179 174 161 154 170 194 160 153 138 163 151 158 146 191 162 174 176 169 132 168 167 157 175 144 157 140 157 148 162 162 167 168 164 160 138 122 150 172 167 157 148 171 186 163 163 174 193 151 142 133 154 151 158 164 149 164 163 159 167 164 171 147 159 139 194 147 169 165 172 159 142 167 139 159 162 163 168 172 160 146 168 155 172 148 129 150 143 164 168 152 181 150 167 175 148 150 126 167 189 128 160 155 161 152 137 139 154 172 172 161 158 147 157 165 155 157 151 151 148 148 139 141 161 150 155 132 133 138 169 153 119 146 161 140 143 159 141 175 154 139 161 149 154 158 146 148 143 143 153 134 146 157 132 146 143 182 138 139 147 150 130 139 159 128 143 141 129 139 147 160 141 146 153 143 181 151 167 126 148 133 165 157 161 141 157 161 139 140 147 153 132 132 144 139 143 128 143 137 167 117 134 147 146 153 130 140 147 161 136 151 147 164 133 130 137 117 157 149 143 154 147 134 139 170 158 130 139 131 138 170 127 148 138 134 160 128 116 134 150 149 127 150 134 155 129 149 158 140 144 126 146 108 117 132 120 152 141 168 111 120 161 139 148 130 140 112 138 119 142 161 137 116 152 137 144 116 121 115 124 150 149 117 146 129 127 143 138 119 131 111 121 139 134 136 137 116 153 158 137 118 117 133 126 152 140 141 126 140 139 140 130 158 127 113 119 143 128 137 133 131 113 110 97 131 129 123 128 126 131 115 120 121 120 120 134 137 123 147 146 141 118 113 143 149 141 127 131 116 105 138 123 118 131 130 138 133 118 150 123 123 132 124 130 121 105 134 126 130 138 113 123 142 130 112 124 128 118 152 122 130 126 128 123 144 131 117 119 124 131 124 150 120 131 115 127 140 143 124 134 132 117 119 126 127 92 129 133 123 120 124 124 122 136 127 102 141 127 122 113 115 131 119 133 124 128 123 123 123 154 117 132 111 132 98 131 129 133 139 123 120 99 103 116 116 121 108 118 138 105 119 113 109 121 124 113 123 111 134 111 127 141 126 131 121 123 122 106 108 109 146 131 115 131 116 117 123 138 107 120 112 136 118 138 115 134 107 126 117 121 138 107 119 98 127 108 128 120 106 111 120 107 111 116 128 108 119 102 131 144 118 95 141 120 113 105 120 130 110 134 105 142 106 108 130 126 113 111 121 113 107 112 111 113 107 123 120 140 130 128 101 120 108 87 99 136 111 120 106 89 126 111 98 127 107 107 128 113 120 107 115 87 105 131 118 123 98 127 110 110 122 95 134 109 103 113 136 109 133 106 126 126 102 113 113 97 102 101 121 109 141 120 123 130 112 120 108 98 112 116 119 131 120 128 100 112 113 87 138 123 92 95 116 132 107 106 101 109 100 91 109 113 124 110 111 116 115 109 106 91 111 110 110 120 102 120 120 94 121 102 105 103 99 118 92 99 107 110 102 126 101 134 109 113 110 113 108 110 99 99 89 82 118 101 101 119 87 118 106 116 134 107 92 115 99 113 112 108 100 106 105 98 91 91 115 109 95 106 117 96 90 116 107 117 102 115 105 108 109 90 101 96 100 102 84 113 126 107 122 106 103 112 101 89 101 97 120 102 110 87 87 116 105 103 94 97 92 102 103 107 105 103 100 101 107 95 82 107 116 107 91 95 94 81 92 115 99 108 107 94 92 98 120 106 103 103 91 107 112 92 100 90 94 87 98 103 97 106 109 99 100 92 79 118 82 87 107 73 94 92 113 103 102 115 95 96 105 78 87 118 105 95 107 96 102 106 102 90 100 97 82 112 103 95 99 94 112 96 113 95 109 116 123 102 117 103 100 100 103 97 95 87 107 111 108 85 100 111 105 88 99 105 88 113 89 86 95 88 102 120 87 92 103 98 92 82 97 84 112 110 109 97 86 117 95 99 92 95 108 84 82 100 90 91 108 95 90 100 97 90 92 77 97 115 86 95 90 109 77 70 97 94 98 94 103 84 96 86 92 98 109 94 96 102 90 91 80 90 106 89 91 107 85 92 109 109 124 105 117 78 88 99 82 107 92 88 82 106 112 87 85 103 86 88 96 87 94 89 92 102 84 102 90 103 112 85 91 77 87 79 81 96 96 99 86 81 109 95 90 90 85 71 78 87 85 101 87 88 82 90 108 91 71 98 89 101 91 78 80 77 90 78 108 81 95 119 100 92 80 99 85 85 115 115 101 91 103 87 86 88 76 89 92 103 86 88 109 69 99 92 92 86 97 82 99 94 99 103 88 90 70 84 96 106 85 98 78 94 97 81 87 85 84 95 110 105 90 107 88 78 96 78 96 86 75 86 81 91 84 102 88 103 92 106 91 70 75 84 105 106 90 84 97 74 76 82 91 73 73 87 92 99 85 78 88 78 90 86 90 92 64 84 73 79 96 96 96 85 80 82 68 84 87 74 97 91 78 84 75 85 89 74 85 92 89 96 69 74 79 85 89 73 84 89 68 75 82 88 92 91 97 101 98 88 78 94 85 98 97 103 118 115 94 115 98 133 103 117 133 108 141 133 149 142 137 152 129 136 113 122 110 118 103 97 96 100 90 98 80 80 90 90 75 84 79 81 98 102 81 78 88 81 84 89 95 82 74 71 85 85 80 81 67 100 87 101 67 95 96 85 84 99 95 89 100 58 73 71 86 80 87 84 86 96 91 75 79 74 65 81 68 76 79 70 82 95 74 80 73 67 87 69 73 79 88 71 70 81 69 92 100 70 81 86 71 70 98 99 63 89 90 85 81 87 85 92 91 86 78 71 65 81 90 68 70 85 88 90 95 69 66 77 67 61 74 70 81 80 65 81 80 78 65 73 78 67 63 88 73 84 71 85 80 68 67 76 76 80 77 88 63 68 68 59 85 87 64 76 75 68 68 88 70 76 84 76 79 65 94 88 61 79 70 85 92 77 70 92 73 87 77 69 94 99 69 76 70 84 85 75 75 78 80 65 78 85 82 74 86 73 102 78 60 79 71 76 76 76 53 74 70 75 70 79 84 76 81 58 87 85 103 85 95 82 71 92 91 90 97 82 103 100 119 111 102 107 126 126 139 122 149 173 163 191 182 204 207 167 159 167 178 165 157 154 141 120 115 124 105 110 97 116 111 107 78 89 69 74 70 67 65 69 82 70 81 81 64 77 82 67 79 69 69 59 79 71 63 69 85 63 77 66 73 78 64 75 71 63 79 86 70 80 49 77 66 95 68 69 81 80 76 74 61 70 58 87 71 77 66 71 79 67 88 66 68 84 59 76 87 79 61 86 58 67 78 63 77 74 74 81 80 71 73 69 63 65 53 86 80 67 85 74 74 73 67 56 77 57 70 75 74 65 64 76 64 73 75 73 74 76 58 66 67 82 73 71 64 89 64 82 67 77 74 67 76 64 75 73 74 66 79 68 66 82 69 57 85 85 85 69 88 79 61 69 73 69 70 78 82 91 73 74 70 77 66 70 63 79 58 75 60 84 67 77 56 84 84 60 74 87 74 59 64 71 71 67 60 77 61 50 79 66 63 56 66 87 67 66 70 77 61 56 73 55 71 65 78 67 77 73 64 56 60 55 74 59 85 64 65 71 86 66 66 76 89 84 70 88 58 80 71 69 77 64 67 77 78 66 79 67 68 74 68 63 69 74 74 76 73 79 69 74 64 65 73 69 74 74 79 68 69 82 79 70 91 69 91 71 76 74 63 68 71 73 70 73 75 70 66 76 74 70 73 63 80 80 67 66 67 69 73 67 68 64 68 75 61 66 66 78 63 76 66 75 70 60 68 74 76 68 74 73 81 77 69 64 66 68 69 55 59 65 59 64 71 76 68 59 68 66 64 70 74 59 65 75 73 67 66 65 78 61 65 49 65 66 60 66 55 73 64 71 58 66 86 66 68 79 64 70 66 65 75 77 76 60 67 66 58 66 71 64 82 64 55 63 65 68 74 56 69 69 59 61 70 78 79 69 65 77 65 56 74 84 63 77 68 63 89 67 73 50 87 65 74 69 77 69 59 57 74 74 82 65 63 75 69 59 90 60 88 71 84 66 71 67 55 76 59 86 47 60 61 66 64 86 60 53 74 81 74 76 94 82 63 79 97 105 102 87 68 102 78 70 92 102 88 76 78 76 78 79 89 85 85 80 71 78 66 81 77 71 74 82 70 71 85 74 64 79 76 78 99 76 70 63 70 67 76 68 79 81 86 68 65 73 86 73 71 92 80 76 78 78 86 69 81 90 66 61 69 67 69 77 76 67 76 66 59 85 55 60 78 69 61 86 77 74 77 67 71 69 76 75 76 86 61 78 66 65 61 59 73 63 71 56 71 81 60 67 58 90 76 78 75 73 71 68 65 74 49 73 84 82 74 74 71 64 64 65 67 65 58 64 67 67 46 79 56 61 73 78 76 64 60 75 70 69 73 66 68 56 54 70 60 65 78 74 65 60 56 66 63 58 60 65 59 87 68 70 68 63 50 70 66 65 49 70 67 70 76 80 78 46 64 75 63 68 65 69 69 71 78 77 86 80 69 85 97 94 79 78 87 98 85 81 92 82 78 82 76 81 85 78 71 67 75 73 60 68 69 60 84 71 65 60 59 81 61 51 55 60 64 57 57 86 70 61 54 84 67 61 61 67 68 68 70 85 70 76 69 90 80 78 79 85 111 89 90 101 113 102 101 108 82 74 107 73 74 89 85 102 80 97 77 94 96 82 84 89 91 86 90 90 118 79 85 96 87 119 91 95 89 92 108 92 80 89 86 81 99 89 77 86 95 78 80 68 108 82 87 97 98 89 98 96 112 100 100 107 97 111 90 106 107 99 85 95 108 110 85 103 85 103 121 101 115 116 134 132 119 122 121 139 144 165 179 173 194 232 232 264 292 318 308 355 410 398 454 481 513 547 634 751 872 1158 1456 1917 2453 3174 4189 4898 5554 5621 5569 5499 5500 5281 5470 5478 5895 5923 6064 5943 5958 5805 5385 4963 4105 3704 3152 2695 2498 2364 2172 2118 1777 1530 1252 1030 816 687 613 484 377 377 310 252 240 247 240 221 207 192 157 189 133 162 139 146 124 130 112 111 109 113 134 94 112 77 113 107 112 106 88 107 98 106 81 106 79 91 94 103 88 76 87 86 103 91 108 92 96 79 85 85 82 63 87 80 74 82 77 78 98 81 71 86 75 71 75 79 70 87 90 82 67 82 88 65 86 74 76 78 68 74 75 79 71 70 78 77 74 73 80 81 80 87 84 85 77 80 68 60 85 63 79 68 66 80 75 79 68 71 70 81 68 73 68 77 66 75 77 70 70 92 74 73 77 58 65 81 69 69 74 70 58 78 67 81 63 89 74 69 63 71 67 78 66 50 67 85 63 57 75 71 74 78 67 90 70 66 70 71 70 69 70 81 49 80 67 66 73 71 73 73 82 68 51 65 64 69 74 76 63 65 69 59 63 71 79 77 60 61 68 67 73 65 96 78 59 67 69 73 67 64 61 64 63 56 73 67 67 81 56 65 81 71 65 68 63 73 70 66 57 69 65 74 73 53 73 77 56 78 74 58 66 76 70 66 54 73 67 74 67 57 78 67 64 64 70 67 67 71 68 66 77 77 71 78 66 59 70 77 71 75 50 81 69 88 73 78 82 68 92 75 106 90 121 137 122 155 168 174 201 157 195 179 205 193 201 207 180 172 195 170 169 162 168 150 148 153 140 142 150 122 120 101 91 96 100 98 71 74 77 69 66 78 69 56 84 59 59 79 66 65 65 65 65 66 67 67 59 48 81 45 58 61 64 65 46 60 68 61 54 65 56 65 63 71 69 58 64 71 48 60 70 58 59 57 68 54 60 74 56 59 71 51 55 55 58 71 61 64 74 57 51 61 39 51 47 65 53 73 59 47 56 65 50 64 63 57 74 56 51 44 55 65 66 53 59 63 57 68 49 44 63 71 59 65 58 64 69 53 59 53 70 66 60 50 55 71 58 54 59 53 69 60 57 47 66 55 43 57 55 54 48 63 45 67 49 54 37 40 59 51 70 60 44 35 63 42 56 67 59 66 55 53 61 59 53 60 49 55 35 56 48 73 53 58 73 68 49 56 61 49 68 60 60 76 66 66 61 67 86 69 85 80 97 121 98 98 101 120 136 139 183 190 216 230 277 306 284 292 266 263 233 217 240 236 252 227 228 219 233 168 173 150 151 161 130 109 113 95 108 86 77 76 90 75 78 86 56 66 76 64 58 64 58 59 53 70 53 61 48 56 59 56 46 43 53 60 46 59 57 53 60 63 56 60 51 60 44 61 64 57 48 56 48 59 61 58 65 61 43 63 53 64 67 53 55 67 55 61 59 51 67 53 50 51 47 51 64 51 51 74 40 57 64 46 51 39 57 64 58 58 49 71 55 65 58 63 47 42 64 45 71 42 67 43 54 50 48 60 49 53 49 59 61 55 64 53 60 57 40 55 50 43 59 61 63 54 46 55 43 39 57 55 61 45 61 63 63 50 51 54 66 50 63 70 56 63 44 59 59 56 61 60 47 48 49 50 60 48 46 55 59 44 46 54 43 51 55 47 54 42 40 54 78 45 51 67 53 53 65 53 51 50 59 64 56 63 69 63 67 77 69 54 75 56 54 47 57 67 46 74 51 55 53 64 67 61 63 65 79 64 73 75 66 75 67 81 106 120 110 102 110 137 162 171 206 263 273 335 335 343 293 339 316 336 293 303 298 329 253 314 284 277 224 213 216 180 154 183 164 133 113 123 112 107 106 90 82 71 85 49 59 49 67 66 86 58 58 56 53 59 53 67 66 54 50 51 54 43 40 48 56 46 51 56 64 56 44 51 40 51 48 59 55 53 59 54 45 48 48 50 48 64 60 45 56 56 53 63 70 46 53 39 51 58 47 57 51 56 49 42 48 43 56 48 44 47 30 39 53 56 50 44 44 43 44 44 49 48 45 44 46 56 42 50 53 46 63 55 40 51 50 39 45 46 37 39 46 49 48 58 59 48 38 45 57 57 45 40 51 44 45 50 37 55 57 47 51 44 60 47 55 53 40 45 43 44 32 60 40 70 39 43 34 42 53 46 48 50 44 42 50 34 47 58 40 61 42 61 46 50 54 46 56 49 56 43 36 35 44 45 44 49 56 46 42 60 47 46 44 49 47 40 51 51 49 45 35 43 39 49 45 32 40 49 53 48 35 44 44 35 51 40 53 48 37 61 43 39 44 45 44 43 65 37 55 53 45 45 47 46 48 48 50 50 42 47 40 54 61 48 61 45 48 40 46 65 55 51 47 51 42 49 33 46 51 49 43 37 40 42 39 63 43 63 29 56 63 55 48 53 47 50 53 56 57 35 57 49 47 51 61 55 44 40 48 58 57 56 51 61 42 58 49 47 53 44 49 45 54 60 38 43 63 40 51 71 55 58 48 61 35 46 57 58 49 40 43 49 55 46 57 55 57 47 46 50 51 48 54 45 51 46 40 55 50 51 69 43 46 47 48 46 50 66 54 49 36 61 60 64 61 35 66 54 54 48 50 56 58 59 73 61 54 58 57 63 55 46 56 49 54 58 53 51 59 68 69 59 59 60 57 47 48 47 45 45 57 58 59 60 65 57 53 50 71 42 67 77 58 67 65 73 61 63 55 69 74 82 78 91 91 98 100 113 124 126 109 144 137 148 154 195 180 203 202 227 234 262 308 325 372 471 616 780 972 1224 1461 1787 1913 2185 2215 2423 2380 2327 2107 1968 1913 1723 1616 1526 1537 1498 1471 1452 1340 1335 1226 1128 1025 869 711 584 475 445 341 311 251 221 190 157 150 117 137 137 102 100 99 102 77 91 96 80 67 67 77 89 66 65 59 63 54 74 65 59 57 61 61 69 59 70 54 48 55 68 48 38 50 56 54 61 46 58 40 60 50 45 55 44 60 44 68 53 49 47 55 49 60 55 51 48 43 44 42 50 48 58 49 43 48 57 56 48 54 42 48 48 51 61 40 58 60 38 40 58 39 40 54 63 51 48 59 44 43 38 49 49 47 51 38 49 56 40 48 63 42 44 37 45 47 43 43 59 33 39 38 56 66 58 51 56 55 55 45 67 50 43 49 55 51 42 53 50 56 58 40 44 35 54 49 51 42 47 56 50 38 54 37 40 48 51 58 55 63 47 48 43 47 50 50 44 60 40 53 44 37 50 44 43 55 45 50 44 53 42 38 45 49 49 49 44 39 46 43 39 44 48 40 50 46 36 33 37 38 36 48 27 55 38 42 58 57 53 47 56 43 36 43 49 54 45 43 60 38 45 54 56 45 51 45 48 42 46 53 57 50 57 58 49 48 40 43 54 51 55 49 43 51 53 57 50 49 46 39 64 54 57 56 49 46 40 47 56 43 44 57 58 56 56 54 61 48 61 45 66 55 57 48 48 51 61 69 58 58 65 68 67 74 58 95 76 68 105 97 92 111 128 136 141 146 158 165 158 160 140 149 124 133 165 123 127 146 143 136 132 121 128 107 120 102 74 99 86 75 68 78 73 69 51 64 61 67 49 49 61 55 69 45 48 49 46 65 45 39 47 46 44 48 65 40 39 49 55 44 40 46 56 63 50 58 47 36 39 54 50 48 44 36 43 42 47 51 36 51 53 53 43 44 43 57 42 53 53 49 55 47 53 53 47 55 37 58 51 54 64 49 44 50 50 53 49 55 42 49 51 48 50 59 51 73 66 60 58 66 80 74 71 76 94 95 84 85 80 108 109 116 128 146 171 200 182 227 277 325 377 439 600 614 731 723 734 647 567 532 464 418 372 336 346 362 369 378 441 426 365 399 307 325 243 267 168 195 152 143 120 106 118 116 82 91 102 94 76 80 64 55 64 63 73 49 74 59 53 61 48 63 61 66 55 67 51 58 56 59 60 63 44 53 60 39 48 50 43 66 53 46 50 48 43 60 46 50 56 57 54 49 34 42 36 58 53 47 53 50 47 48 59 42 36 48 44 53 43 50 53 49 44 46 45 45 58 49 45 59 48 53 49 54 46 54 73 49 47 64 39 46 37 43 44 56 50 51 49 40 56 63 40 47 44 42 47 48 42 35 34 49 49 48 49 53 35 47 54 44 33 45 64 38 36 55 44 38 42 30 38 40 40 46 45 40 34 54 44 48 40 38 46 58 47 43 36 47 49 58 36 47 57 42 44 38 47 57 58 43 43 46 38 44 49 49 53 42 33 53 37 47 45 34 42 39 38 48 46 53 35 37 47 49 36 42 46 38 38 30 47 42 32 34 42 46 37 44 42 40 43 47 45 46 36 35 38 54 50 39 37 48 40 42 40 43 38 46 40 48 42 42 33 38 35 45 55 39 44 50 45 44 37 39 51 50 37 39 37 34 47 46 39 39 36 47 49 39 43 39 36 49 42 47 34 50 44 38 38 38 40 46 47 30 34 46 54 30 43 37 54 42 43 44 47 38 32 32 45 45 38 46 49 38 47 35 33 38 37 34 38 47 43 36 38 37 48 56 43 47 42 45 43 57 29 47 51 42 49 65 44 36 29 37 42 39 48 39 33 35 33 24 48 51 46 44 46 45 39 45 42 37 35 38 42 38 46 44 44 50 39 40 35 50 38 51 48 36 40 45 40 37 54 46 59 42 40 43 28 38 32 36 48 35 43 44 39 47 46 40 38 54 39 48 50 44 42 49 39 43 38 53 48 37 39 36 40 38 35 38 36 39 47 38 48 53 43 34 43 36 46 43 48 43 44 42 43 37 46 40 46 47 54 39 44 44 48 49 45 53 37 43 49 48 32 49 45 38 48 32 50 38 49 37 36 46 40 56 43 48 30 33 50 46 36 50 50 48 51 42 60 44 37 48 44 50 48 59 45 56 55 37 51 57 49 48 39 44 46 46 50 74 59 53 57 55 57 45 58 63 76 50 84 74 94 103 134 102 170 182 182 194 210 217 199 179 157 140 139 143 140 134 142 154 124 129 172 149 147 155 123 137 129 109 108 81 80 79 64 56 74 55 74 67 57 61 45 56 55 47 63 63 53 67 45 47 53 56 38 55 47 51 67 59 45 33 43 50 66 47 54 57 36 58 49 53 45 39 54 45 42 53 48 56 45 47 54 26 49 66 48 60 34 35 50 54 42 44 50 35 46 56 61 58 56 49 61 49 42 39 58 37 60 46 45 49 43 48 54 68 54 47 60 55 59 86 65 67 65 67 64 77 84 76 84 75 82 102 87 86 91 115 123 116 107 116 129 140 170 180 215 226 276 303 363 408 509 592 780 874 1033 1221 1390 1520 1485 1414 1228 1096 929 788 766 690 613 664 640 711 755 777 888 884 845 805 730 669 575 461 432 353 335 285 240 210 221 180 173 180 164 174 154 161 136 172 161 157 154 161 144 178 192 196 217 221 259 290 300 346 416 486 549 648 683 845 849 941 992 1009 1122 1237 1302 1268 1409 1426 1378 1289 1307 1147 1131 1020 968 912 832 809 842 805 838 859 786 774 819 720 678 574 527 492 422 357 301 303 242 224 211 155 176 141 165 141 123 88 127 100 113 90 95 75 86 74 71 74 78 66 66 58 58 70 57 73 65 47 69 53 64 60 56 48 57 59 60 55 48 66 48 40 49 53 54 53 56 30 48 48 48 43 46 38 43 48 43 45 43 39 46 38 49 35 42 55 45 39 40 47 57 42 47 36 39 44 42 39 48 50 48 38 34 46 51 46 45 43 38 39 46 49 45 43 45 37 54 44 39 49 32 55 45 47 45 45 32 44 45 43 37 53 37 37 39 38 39 38 53 35 40 54 46 58 42 36 37 60 51 45 35 30 50 53 46 45 44 45 38 45 48 54 42 54 47 60 38 45 33 50 46 46 42 45 32 36 44 45 36 42 59 43 34 51 36 51 43 28 45 35 54 48 46 37 40 32 38 39 51 33 33 42 39 42 33 32 55 47 43 36 39 29 40 29 37 38 32 49 44 49 38 26 47 36 42 34 45 33 36 33 29 38 39 37 37 35 30 46 35 46 36 47 34 40 36 32 38 35 34 42 38 37 42 40 35 36 42 40 37 43 39 36 51 42 40 35 42 38 46 38 42 38 40 51 47 37 42 33 40 38 42 57 39 39 42 36 35 47 42 43 34 35 29 51 54 45 49 34 35 28 37 48 32 27 28 35 43 34 35 46 51 33 32 37 25 29 35 53 27 25 33 53 37 48 38 36 42 45 43 37 40 47 35 35 45 33 33 32 28 40 29 29 36 42 38 26 36 22 35 39 38 49 48 37 42 36 36 34 36 32 30 37 33 27 43 36 49 34 35 40 40 34 29 34 36 38 39 34 43 35 37 42 34 46 33 38 33 40 35 26 34 27 34 44 36 43 37 33 44 46 42 29 40 28 54 21 37 34 36 36 37 35 29 42 36 35 33 26 50 25 36 39 55 48 46 42 36 36 43 32 37 39 32 45 34 39 40 35 42 39 51 42 46 34 44 32 42 35 47 58 46 39 44 29 37 36 29 37 38 32 46 38 39 37 38 49 49 30 39 36 48 30 37 37 47 33 43 38 37 33 39 30 34 45 40 48 50 34 38 30 25 36 38 35 36 35 35 32 37 35 39 37 40 26 30 36 28 26 42 45 36 39 24 42 38 39 45 29 37 38 39 47 38 45 53 43 42 42 51 26 42 38 30 38 32 33 34 32 58 47 33 43 33 37 40 33 30 39 43 35 32 35 38 28 32 38 32 44 38 30 34 43 43 38 33 28 38 25 25 35 28 32 27 35 36 38 46 40 40 35 48 38 40 29 39 24 38 29 32 38 32 36 46 44 29 38 40 47 36 35 35 30 34 36 26 35 37 38 39 36 42 54 34 44 42 28 45 38 38 39 27 34 33 23 34 34 35 38 36 29 36 23 27 43 37 29 42 29 35 23 26 28 48 32 25 32 37 35 36 22 33 36 33 38 40 39 37 37 30 28 25 24 30 37 36 29 30 27 26 33 23 24 28 27 42 26 34 27 32 47 27 42 34 44 30 37 35 38 28 37 28 30 37 27 34 27 33 43 36 44 44 39 28 30 43 50 54 42 36 30 39 43 36 36 24 23 34 32 26 32 35 30 35 30 33 30 39 40 44 30 26 39 30 35 32 39 35 37 36 35 34 42 45 38 24 32 34 40 39 33 37 54 32 35 33 32 30 42 28 37 26 32 39 30 35 37 37 30 32 38 37 32 33 36 33 32 45 38 47 42 34 28 33 37 30 33 44 34 33 35 26 27 45 45 44 37 35 35 26 33 29 27 27 30 28 35 30 33 33 36 40 32 35 24 30 47 37 37 28 42 35 33 39 30 38 34 36 35 36 26 29 27 36 42 39 38 37 33 36 28 46 34 38 37 39 33 19 29 35 37 42 40 32 45 35 35 27 34 30 38 38 36 33 43 29 35 32 32 38 33 35 36 21 34 36 29 30 37 33 38 30 30 35 24 43 28 33 46 33 30 33 30 50 33 47 42 36 47 28 36 25 39 53 40 40 45 39 39 49 54 36 57 66 61 43 56 59 78 75 75 86 108 115 106 102 117 116 128 101 85 81 97 87 79 106 75 76 89 75 76 70 75 84 90 89 90 78 89 68 64 66 68 60 47 59 63 43 42 39 50 42 29 48 39 46 37 46 44 33 39 37 29 36 43 40 38 33 40 43 48 40 42 39 40 33 44 32 46 35 35 51 46 40 35 42 36 45 34 36 39 37 44 44 44 40 44 47 43 48 40 50 50 50 56 57 66 69 54 58 73 79 75 98 101 94 138 122 141 161 191 213 197 228 247 256 252 270 232 226 261 223 200 189 192 197 185 142 189 157 153 197 176 176 185 180 188 162 153 140 141 160 139 97 102 95 85 87 80 77 61 71 63 59 48 59 56 45 38 53 38 45 39 45 44 46 44 30 40 48 35 44 21 34 37 47 32 30 42 44 34 43 33 39 30 30 36 30 38 24 38 32 33 35 34 42 30 32 43 27 26 32 36 32 30 33 54 40 28 36 28 28 35 29 46 24 36 44 26 35 35 27 26 36 32 27 39 33 34 42 26 39 24 25 35 30 46 34 38 32 29 36 30 37 42 32 36 30 27 42 35 38 43 32 29 29 24 23 32 36 35 29 37 30 36 37 32 38 33 36 39 39 32 30 39 32 29 32 35 34 32 30 28 32 32 42 19 26 29 45 37 32 40 37 32 39 27 34 27 47 42 36 34 27 37 26 27 32 27 29 39 28 30 36 32 35 27 25 38 30 22 33 42 38 36 32 32 33 35 35 40 28 34 22 32 33 19 30 25 45 32 46 36 37 38 28 33 23 26 39 17 37 43 35 42 36 43 34 45 40 58 34 39 34 35 54 44 54 49 49 66 71 66 74 47 49 59 58 64 63 48 44 70 57 51 59 54 53 46 55 48 43 59 46 51 43 50 44 54 47 61 36 42 46 40 29 39 50 38 55 45 39 36 46 47 32 37 36 36 32 38 35 38 34 28 36 29 42 33 44 35 24 38 27 42 23 25 32 28 34 37 30 29 27 46 28 35 30 34 30 37 28 27 35 46 36 36 43 37 23 33 36 51 36 26 37 43 38 36 38 49 27 25 36 24 28 29 36 33 32 36 38 28 24 32 40 22 44 46 37 30 36 34 33 34 23 29 35 37 19 40 30 34 33 33 34 37 39 39 42 38 44 35 34 42 37 34 46 28 45 37 37 44 38 38 51 49 47 48 57 45 51 69 61 77 65 69 73 100 86 77 101 115 142 144 175 158 189 150 173 174 176 163 176 157 181 170 155 147 115 130 122 126 102 139 106 117 133 118 115 123 118 117 127 105 92 103 87 92 96 90 67 63 64 65 60 57 59 59 45 36 46 47 44 53 50 39 39 42 36 53 40 28 43 37 33 38 32 48 35 32 39 38 35 45 42 27 33 61 44 33 32 39 27 39 35 36 43 40 33 40 35 27 44 44 34 45 35 45 36 50 57 49 50 32 43 32 63 27 42 47 50 66 44 59 70 46 65 61 71 101 94 89 136 138 179 247 231 286 306 339 404 410 409 347 347 320 318 268 254 221 203 162 188 173 185 158 190 180 214 222 234 237 252 256 235 197 211 180 176 152 168 128 131 112 106 94 85 88 90 59 79 61 64 59 46 55 58 59 54 45 57 49 36 50 51 49 39 45 43 68 57 42 48 47 44 61 55 46 57 67 67 80 55 73 118 90 103 120 102 111 141 158 134 155 169 128 167 146 159 146 139 136 138 127 96 110 91 97 85 94 124 94 96 111 97 79 98 98 116 103 101 84 79 78 64 75 75 67 67 63 61 38 37 37 49 36 46 56 46 49 48 48 39 29 24 19 38 36 32 37 38 44 40 49 42 36 39 33 23 36 24 38 32 43 42 37 44 28 32 42 34 35 39 44 48 44 37 35 36 32 39 53 47 55 47 47 48 44 54 40 48 43 60 57 65 75 55 74 75 73 97 87 88 105 91 96 97 94 88 95 82 61 77 88 64 68 65 45 63 43 64 80 63 73 80 65 68 79 70 61 78 47 60 53 54 49 57 45 49 47 53 34 27 37 36 37 39 50 37 29 36 29 43 46 32 30 23 42 33 30 36 38 22 40 28 27 22 36 40 26 49 39 39 34 23 25 23 40 29 39 36 36 47 32 35 35 35 47 30 39 39 27 34 21 36 37 44 16 38 34 37 24 32 46 38 28 37 30 34 35 25 42 37 34 29 32 39 50 30 28 37 37 47 28 33 36 32 40 48 50 51 28 28 38 57 47 51 48 43 53 38 58 48 55 53 51 65 67 53 70 79 69 82 105 102 108 110 141 150 157 152 149 158 158 153 152 157 144 140 157 122 123 124 95 94 117 96 105 113 108 105 86 116 109 109 105 111 99 90 106 106 79 65 80 57 71 55 50 64 59 61 50 57 44 38 34 49 39 51 42 43 44 35 26 48 33 40 45 35 32 35 26 21 38 27 42 27 37 24 42 36 34 33 26 28 29 26 28 26 34 28 33 44 44 27 35 24 37 33 36 37 28 32 35 35 34 44 34 24 27 18 24 29 29 30 25 30 34 34 35 32 40 34 39 36 25 30 44 33 23 30 24 37 21 30 26 26 30 38 29 30 23 37 34 26 37 26 23 32 24 30 19 28 28 26 43 25 33 32 38 33 23 33 21 35 27 32 39 27 30 15 27 27 23 30 24 35 25 28 35 39 40 36 33 28 29 30 25 28 37 28 33 33 27 39 28 34 28 29 23 30 38 28 34 26 38 39 34 37 25 30 33 26 30 27 45 39 32 30 35 32 37 32 34 26 39 42 29 21 34 25 18 30 30 24 26 22 26 21 19 27 36 23 33 26 35 29 38 30 32 28 38 35 35 28 39 40 30 24 27 27 28 21 30 26 26 32 28 33 35 19 24 15 27 34 24 24 26 36 33 26 27 39 38 32 28 26 29 32 38 25 27 27 28 36 28 35 27 28 33 26 36 32 30 40 34 38 33 30 29 39 27 38 30 38 43 28 40 35 34 30 39 32 29 19 32 30 24 37 44 33 35 43 35 34 32 36 25 26 28 32 35 30 27 35 28 40 30 36 38 44 29 51 43 46 48 30 37 29 34 36 35 40 36 47 59 38 50 40 54 61 65 63 59 73 50 78 64 64 81 70 88 71 78 70 59 78 73 69 61 59 65 58 60 74 74 58 58 61 74 58 63 60 59 75 59 61 66 47 51 47 47 36 63 44 51 47 44 45 55 40 39 46 35 33 45 39 25 37 30 21 32 36 37 36 33 35 36 26 39 22 40 33 28 25 35 35 38 37 32 29 23 24 33 37 30 34 26 26 30 38 28 29 39 32 34 33 28 28 27 40 30 27 30 29 37 36 22 27 25 28 32 38 11 27 28 25 33 21 33 33 27 23 34 21 26 24 35 25 28 30 30 33 37 35 25 36 27 36 28 27 28 26 36 30 28 26 29 32 27 26 34 32 23 28 27 26 27 37 25 26 25 23 36 43 19 22 26 24 27 28 25 33 27 21 36 25 28 25 46 33 32 23 32 32 33 32 28 26 28 33 27 26 28 32 35 35 34 26 40 23 35 36 25 34 19 33 25 27 21 36 33 27 39 36 19 37 35 26 33 35 16 29 27 27 38 32 33 35 32 24 25 28 30 26 26 25 24 30 28 21 36 30 28 23 19 25 27 33 23 25 29 32 19 30 34 35 29 26 36 38 38 30 23 42 29 32 36 37 23 30 43 40 42 30 27 39 36 43 40 40 40 34 40 53 57 36 51 44 55 43 55 48 73 79 78 85 92 89 89 81 91 69 78 78 50 73 67 59 56 69 49 57 59 63 53 50 51 57 48 58 64 65 68 46 54 60 46 55 49 46 53 36 37 30 40 40 39 38 44 29 45 26 32 26 27 25 30 28 33 32 30 32 36 24 24 33 30 28 30 36 29 26 32 26 27 35 33 29 33 30 25 28 29 22 29 26 15 33 22 27 33 30 35 39 32 26 32 40 36 27 46 32 38 29 27 30 29 29 36 32 29 25 42 30 30 30 23 23 18 25 25 35 39 32 25 38 27 39 34 32 29 25 38 38 27 25 24 33 32 33 24 34 22 24 23 18 34 27 35 28 23 23 29 28 28 24 35 34 25 30 30 25 28 32 28 34 26 37 32 36 34 33 27 27 30 23 36 29 34 22 25 23 29 24 29 36 37 37 24 27 37 33 40 34 33 37 39 35 47 32 38 44 34 35 42 34 38 40 46 56 51 40 51 60 45 58 70 77 76 65 71 67 64 73 67 74 88 73 73 87 67 66 69 58 71 87 65 75 53 50 64 70 51 69 49 57 63 71 71 67 70 57 51 56 64 57 50</intensities></dataPoints></scan></xrdMeasurement></xrdMeasurements>