File: data/XRD/data/WhiteSaddleDolomite_std.xrdml
<?xml version="1.0" encoding="UTF-8"?>
<xrdMeasurements xmlns="http://www.xrdml.com/XRDMeasurement/1.0" xmlns:xsi="http://www.w3.org/2001/XMLSchema-instance" xsi:schemaLocation="http://www.xrdml.com/XRDMeasurement/1.0 http://www.xrdml.com/XRDMeasurement/1.0/XRDMeasurement.xsd" status="Completed"><sample type="To be analyzed"><id></id></sample><xrdMeasurement status="Completed" measurementType="Scan"><usedWavelength intended="K-Alpha 1"><kAlpha1 unit="Angstrom">1.5405980</kAlpha1><kAlpha2 unit="Angstrom">1.5444260</kAlpha2><kBeta unit="Angstrom">1.3922500</kBeta><ratioKAlpha2KAlpha1>0.5000</ratioKAlpha2KAlpha1></usedWavelength><incidentBeamPath><radius unit="mm">240.00</radius><xRayTube id="1010041" name="PW3373/00 Cu LFF DK184033"><tension unit="kV">45</tension><current unit="mA">40</current><anodeMaterial>Cu</anodeMaterial><focus type="Line"><length unit="mm">12.0</length><width unit="mm">0.4</width><takeOffAngle unit="deg">6.0</takeOffAngle></focus></xRayTube><sollerSlit id="21010002" name="Soller 0.04 rad."><opening unit="rad">0.0400</opening></sollerSlit><mask id="22080002" name="Inc. Mask Fixed  10 mm (MPD/MRD)"><width unit="mm">6.60</width></mask><antiScatterSlit id="22010003" name="Slit Fixed 1°" xsi:type="fixedAntiScatterSlitType"><height unit="mm">1.52</height></antiScatterSlit><divergenceSlit id="22010004" name="Slit Fixed 1/2°" xsi:type="fixedDivergenceSlitType"><height unit="mm">0.76</height></divergenceSlit></incidentBeamPath><beamKnife id="29010002" name="Beam Knife for X'Celerator"/><diffractedBeamPath><radius unit="mm">240.00</radius><sollerSlit id="21010002" name="Soller 0.04 rad."><opening unit="rad">0.0400</opening></sollerSlit><filter id="20010004" name="Nickel"><material>Ni</material><thickness unit="mm">0.020</thickness></filter><detector id="7010013" name="X'Celerator" xsi:type="rtmsDetectorType"><mode>Scanning</mode><activeLength unit="deg">2.122</activeLength></detector></diffractedBeamPath><scan appendNumber="0" status="Completed" mode="Continuous" scanAxis="Gonio"><header><startTimeStamp>2009-08-17T19:45:01</startTimeStamp><endTimeStamp>2009-08-17T19:56:39</endTimeStamp><author><name>Administrator</name></author><source><applicationSoftware version="2.0">X'Pert Data Collector</applicationSoftware><instrumentControlSoftware version="1.5 ">XPERT-PRO</instrumentControlSoftware><instrumentID>0000000013030094</instrumentID></source></header><dataPoints><positions axis="2Theta" unit="deg"><startPosition>5.00417782</startPosition><endPosition>74.99932830</endPosition></positions><positions axis="Omega" unit="deg"><startPosition>2.50208891</startPosition><endPosition>37.49966415</endPosition></positions><commonCountingTime unit="seconds">10.160</commonCountingTime><intensities unit="counts">1253 1338 1304 1246 1236 1267 1236 1245 1268 1239 1231 1237 1258 1289 1214 1213 1217 1141 1245 1179 1190 1153 1189 1228 1190 1211 1236 1214 1179 1212 1114 1156 1206 1190 1138 1183 1204 1243 1165 1221 1176 1172 1147 1110 1234 1143 1108 1176 1140 1173 1150 1201 1160 1137 1151 1152 1199 1112 1151 1129 1151 1143 1196 1140 1177 1119 1142 1145 1117 1116 1142 1166 1131 1129 1093 1116 1145 1147 1090 1153 1109 1126 1096 1097 1051 1133 1059 1118 1088 1133 1044 1113 1071 1062 1049 1072 1065 1045 1114 1108 1100 1118 1074 1101 1108 1126 1077 1013 1079 1103 1019 1099 1086 1006 1055 1109 1081 1058 1121 1037 1095 1056 1103 1031 1024 1069 1051 1100 1040 1060 1072 1092 1035 1051 1008 1020 1120 986 1058 1026 1075 1049 1043 1016 1055 994 1086 989 1030 1043 949 1029 1015 1083 974 1068 1016 1041 1046 1062 1015 1022 1023 1035 1006 1029 1049 1037 1015 964 1061 1081 1071 1017 968 1001 1062 1027 1041 926 1013 1057 1006 984 1046 951 972 1033 975 983 922 989 1014 1008 1003 966 962 1022 1039 960 993 952 1013 1030 996 1037 1004 992 978 1013 949 1043 1002 958 987 1013 992 1018 1038 975 918 937 954 985 967 996 996 939 988 918 994 1087 960 960 913 885 945 976 976 984 960 929 956 947 950 966 943 956 950 962 939 986 944 1017 970 954 937 1009 964 946 989 942 991 1006 932 936 970 977 967 939 963 956 933 937 977 957 935 950 940 906 928 895 955 888 928 941 916 998 954 915 939 885 958 931 977 944 943 925 949 871 964 930 945 981 924 987 915 889 980 954 898 924 993 944 850 934 906 915 935 919 947 919 919 932 911 908 866 944 922 901 900 915 933 946 923 899 914 893 955 889 848 913 858 898 888 919 872 923 911 882 932 866 884 891 957 920 918 923 863 929 878 895 903 915 903 933 898 878 921 921 909 913 866 901 910 982 920 890 837 905 902 904 864 924 839 910 885 862 843 891 914 890 932 874 954 941 933 920 873 914 898 915 928 934 933 928 850 946 885 904 847 916 889 903 928 951 863 876 861 889 942 921 879 909 879 902 832 847 808 810 926 892 871 818 895 874 853 895 877 897 846 851 901 957 857 866 858 889 873 902 879 800 903 871 814 928 832 919 914 835 921 805 830 903 858 900 843 855 879 879 847 888 842 900 841 821 841 812 856 846 905 858 891 891 879 857 905 855 838 900 830 817 850 846 890 818 887 897 889 859 853 840 847 883 821 806 847 847 872 852 858 846 806 849 774 818 851 821 877 806 928 877 881 820 829 845 878 839 837 878 829 839 799 862 891 905 849 880 845 892 866 798 871 860 857 787 864 818 894 851 855 828 824 816 849 919 798 829 855 824 810 841 870 805 820 867 874 842 784 803 819 824 791 849 843 862 830 908 860 791 795 833 843 809 786 864 767 814 883 799 838 835 861 812 833 838 840 853 789 926 830 846 851 833 784 838 786 816 836 788 862 808 859 811 811 777 824 799 862 806 870 810 878 832 841 819 824 811 725 807 798 863 793 787 812 779 795 811 830 775 818 832 788 797 803 762 780 780 809 764 852 840 829 795 822 801 808 812 749 705 821 825 799 793 814 758 826 766 768 842 836 803 809 848 801 818 796 816 775 798 782 782 775 787 767 816 765 776 804 779 745 845 772 847 744 838 853 793 787 808 791 794 821 815 859 760 826 783 801 755 767 794 809 773 755 819 782 767 788 720 759 795 728 764 801 804 774 807 797 786 826 807 857 822 774 832 796 748 768 809 776 748 807 758 796 828 815 796 772 749 816 773 786 759 795 773 787 815 762 805 778 774 687 791 774 733 760 700 758 778 779 789 795 776 773 780 773 797 755 732 728 741 741 715 699 693 793 727 755 728 793 762 770 745 783 773 764 780 738 673 723 739 739 733 747 758 783 776 788 731 779 764 718 724 709 758 765 726 706 736 797 778 789 728 779 788 762 736 710 739 723 782 702 760 742 745 773 733 775 754 756 772 789 763 732 714 722 736 794 731 745 743 763 724 756 766 703 702 757 757 716 753 755 709 730 748 728 711 680 718 756 745 711 738 724 711 725 720 758 754 741 705 738 721 714 679 748 716 680 745 699 766 669 665 723 736 716 705 699 686 711 707 726 687 736 762 772 679 712 704 709 769 769 738 732 726 725 707 743 651 744 674 689 710 670 670 718 713 695 696 706 661 723 705 702 707 722 759 735 715 710 664 714 641 664 699 701 707 706 712 736 691 691 662 655 706 671 720 641 691 735 685 661 670 610 679 683 657 679 638 663 660 717 685 655 701 702 681 692 704 666 654 657 671 638 675 687 644 654 662 680 655 666 701 642 700 703 658 652 618 690 696 663 670 689 650 661 657 662 590 650 631 660 663 651 680 648 664 634 717 659 651 618 657 618 654 648 681 619 641 616 636 647 673 649 680 634 596 621 657 603 645 640 566 644 629 638 612 631 634 631 661 627 633 630 669 632 685 647 658 629 632 632 623 679 607 631 598 636 593 658 632 639 590 673 629 617 620 602 657 595 602 640 620 617 614 605 607 596 603 623 616 558 624 580 634 641 606 643 579 658 650 631 581 587 605 567 607 618 600 574 609 616 633 638 571 632 605 587 587 551 579 597 553 553 570 574 550 566 580 579 596 565 563 565 597 585 630 571 619 568 593 581 591 576 574 548 570 618 614 600 540 600 581 548 570 566 590 611 572 595 556 588 584 550 533 579 590 581 550 505 556 549 548 565 569 507 563 554 587 546 554 590 488 620 590 546 550 581 557 577 609 586 569 544 549 571 559 554 548 529 560 516 578 546 530 556 536 549 544 516 601 553 578 550 588 549 558 609 570 569 549 578 533 534 517 572 487 557 545 559 569 534 503 523 579 549 569 561 491 509 529 511 493 533 512 544 488 518 483 517 535 536 515 488 504 497 529 538 515 558 515 522 505 520 493 499 504 515 509 549 513 537 530 533 459 476 511 497 497 505 498 523 494 514 481 506 486 538 513 459 488 493 505 507 512 523 541 482 451 466 468 483 523 519 459 465 483 497 480 506 455 484 482 535 498 501 480 514 508 491 452 508 475 466 506 449 491 419 465 405 464 449 445 476 493 494 463 468 505 491 501 450 432 477 472 465 443 444 490 467 470 454 450 505 445 463 461 474 456 459 499 430 426 474 452 420 443 480 450 403 487 457 446 428 442 431 453 454 409 433 454 454 428 418 475 419 422 405 456 426 408 434 455 472 443 449 449 424 461 415 416 439 440 412 454 412 405 447 411 431 439 426 430 434 450 451 418 416 471 394 426 416 439 428 405 386 388 412 389 389 419 432 435 397 400 411 422 451 403 424 407 430 398 405 428 386 405 425 411 410 409 387 400 405 430 397 395 402 400 404 390 339 407 400 373 392 424 392 384 374 411 386 402 409 399 389 415 358 387 346 372 378 361 379 387 392 353 416 400 404 419 379 386 388 386 391 388 393 363 376 395 341 407 348 387 373 340 384 379 369 373 404 371 391 377 370 372 372 348 321 391 356 359 361 371 380 362 357 369 365 415 340 350 366 382 363 336 404 401 386 394 379 381 340 362 378 346 414 360 365 350 345 334 373 331 389 353 365 365 336 341 359 399 368 370 337 335 369 363 347 336 337 337 367 363 343 345 355 363 347 379 337 342 341 332 358 328 366 366 338 391 374 365 311 342 326 321 335 335 362 332 363 313 318 303 331 338 356 339 377 337 315 332 345 338 297 330 358 328 345 321 322 310 297 374 332 345 346 345 316 338 319 339 332 306 326 306 356 347 297 341 360 340 349 346 320 330 336 353 328 315 336 318 309 311 341 341 322 283 310 297 307 347 310 363 352 365 359 309 299 332 332 334 313 334 305 300 318 303 322 310 285 329 311 324 350 336 330 292 311 316 337 346 295 293 350 293 346 305 331 288 318 307 288 325 332 311 316 326 321 298 325 286 297 303 342 304 326 314 314 308 318 283 277 334 328 310 308 319 297 293 232 270 328 289 335 287 300 266 309 295 329 292 259 295 305 274 292 278 301 317 327 320 277 277 311 275 297 276 293 268 300 284 314 292 283 273 330 248 301 322 286 279 303 301 294 273 280 257 292 294 322 279 294 297 289 324 297 285 303 299 268 305 292 309 286 296 298 283 273 289 268 283 297 274 275 272 275 297 266 285 278 265 300 294 278 262 282 241 286 287 297 290 262 296 275 277 270 257 292 259 280 275 318 289 279 286 270 253 255 278 286 287 274 297 273 289 280 266 256 288 263 277 252 274 261 307 280 252 280 287 284 273 284 310 292 284 274 278 286 255 249 264 246 269 230 269 277 262 226 289 300 261 274 257 253 256 242 256 251 285 273 262 244 266 272 247 269 257 273 247 235 269 300 265 257 242 253 282 257 270 200 248 313 270 273 258 247 265 269 241 280 240 228 251 261 254 243 270 251 235 243 286 211 244 225 223 278 282 243 269 283 248 284 274 238 236 252 242 256 261 228 236 237 224 249 244 220 257 230 257 243 240 243 242 249 258 233 240 245 241 222 251 233 255 225 220 244 246 213 243 227 254 266 219 251 251 263 249 235 231 247 225 245 206 252 228 249 230 226 235 234 224 222 240 221 234 234 227 236 241 256 248 215 240 194 211 211 210 221 227 234 228 226 235 235 240 245 251 228 212 245 226 200 235 215 214 220 257 252 221 216 227 220 261 243 228 255 225 265 248 240 240 261 234 225 216 256 210 236 246 235 227 242 221 215 217 227 219 215 200 221 223 223 225 238 206 217 252 206 215 214 176 204 206 205 204 220 220 213 206 213 186 210 193 214 212 223 212 204 192 210 232 217 231 186 210 220 215 192 183 192 205 195 202 205 193 210 203 196 201 209 183 207 195 200 227 186 202 214 196 181 181 204 189 184 182 204 182 194 186 216 210 172 223 188 179 226 184 180 182 202 189 216 172 192 202 221 210 215 202 176 188 199 186 186 197 171 238 176 188 169 178 202 212 193 186 204 181 227 159 206 192 199 215 184 163 197 175 201 202 172 212 183 178 183 152 182 185 211 200 201 176 212 163 214 183 194 223 181 191 188 186 195 185 184 189 193 196 162 194 163 211 172 178 181 170 183 168 152 165 185 185 163 199 172 203 197 189 180 182 182 181 193 170 153 180 181 185 213 195 186 189 178 176 189 183 176 171 197 183 175 158 140 175 178 181 189 188 195 192 190 175 202 186 185 184 206 162 197 278 230 252 245 298 273 268 317 308 270 270 270 272 289 278 296 270 235 252 227 246 192 210 212 217 191 192 173 175 201 201 169 195 165 184 200 185 190 175 197 173 167 191 178 173 159 188 165 173 161 189 172 171 184 165 185 165 170 159 196 190 158 137 185 176 154 151 155 181 193 171 147 151 172 182 168 153 147 131 164 167 162 165 165 167 191 149 178 140 151 165 163 157 171 162 172 183 148 170 173 164 181 183 172 176 190 178 178 165 161 151 164 172 165 148 161 160 160 171 179 174 147 150 167 159 169 186 141 176 161 160 170 167 162 167 186 188 140 183 160 147 170 134 174 149 175 157 157 167 171 180 159 170 147 159 139 141 167 147 157 160 162 182 181 182 159 148 158 151 168 129 173 165 151 163 161 138 168 147 158 169 147 147 180 164 165 139 146 155 148 186 167 175 158 157 168 163 197 189 164 165 163 137 180 176 146 162 170 137 139 178 154 162 158 164 129 167 173 138 159 154 158 146 159 164 147 147 170 185 136 126 170 144 172 163 150 146 147 165 161 151 174 170 164 147 142 193 134 138 175 169 158 133 153 178 130 164 137 139 133 142 154 153 146 158 173 148 139 159 132 133 147 147 131 144 155 178 154 120 160 153 164 139 179 154 141 139 173 163 157 153 152 149 142 148 133 153 162 157 164 167 176 150 192 142 139 148 167 152 150 158 159 149 158 175 186 176 160 134 172 148 158 146 155 150 119 163 163 151 164 161 169 157 164 155 159 179 153 202 113 173 149 175 173 168 159 159 152 152 152 160 150 169 171 163 171 162 176 143 180 167 169 174 161 154 167 172 146 173 175 150 190 148 147 164 164 167 151 149 182 169 182 172 163 161 138 170 129 138 179 159 168 150 176 157 139 161 139 158 169 149 149 168 158 184 159 152 169 164 174 163 160 165 157 179 169 162 163 160 154 170 179 152 154 169 170 160 170 209 169 172 164 183 171 155 189 124 199 167 186 191 175 160 151 186 178 173 189 169 184 172 181 197 194 205 221 197 221 261 221 261 249 252 234 289 258 276 290 274 295 294 288 301 287 280 256 248 228 254 234 236 247 196 224 228 211 195 206 213 197 196 202 206 197 203 215 179 202 213 203 204 169 190 185 186 178 167 196 182 189 186 180 178 160 172 210 196 172 176 216 207 185 192 180 200 186 190 174 160 191 178 201 197 180 204 172 189 185 222 186 210 169 178 186 185 172 190 191 169 199 213 214 176 207 169 171 174 168 210 203 186 193 193 161 186 192 158 184 192 188 182 185 182 210 179 195 212 179 220 183 191 178 182 183 206 202 197 195 220 209 185 205 210 217 212 203 194 195 183 200 190 190 182 217 204 190 206 204 202 196 216 233 184 213 194 213 220 212 223 230 236 202 200 206 234 200 238 216 224 237 223 267 256 235 261 263 212 269 247 258 241 284 264 296 300 311 268 336 342 322 316 347 328 352 369 327 337 382 303 334 308 306 310 309 313 318 331 319 341 355 339 314 342 357 337 330 325 348 331 294 286 296 319 324 317 283 274 294 316 334 339 317 305 304 320 338 362 343 349 343 346 350 382 377 379 398 425 415 434 414 404 463 460 488 446 532 464 461 530 477 505 484 477 471 485 480 490 520 454 536 505 532 525 514 509 556 495 508 512 532 532 538 560 557 514 538 570 524 513 544 561 561 574 553 588 598 515 592 553 613 637 596 652 634 655 611 681 640 599 598 661 588 676 714 705 647 692 782 744 773 795 868 848 879 873 978 1015 1102 1065 1177 1268 1330 1398 1370 1610 1669 1783 1827 1943 2104 2135 2278 2422 2483 2671 2683 2865 2961 3150 3280 3540 3777 3984 4247 4477 5000 5320 6034 6659 7674 8983 10338 12522 14802 17572 19706 21433 22691 24224 25937 28068 30170 32868 35086 36814 37438 38144 37814 37428 37081 35877 35181 33810 31903 29776 27920 25732 23964 22293 20672 18600 16974 15581 14563 13606 12588 11227 9821 8622 7284 6605 5646 5205 4989 4760 4390 3872 3484 3072 2568 2141 2000 1838 1739 1627 1441 1318 1203 1141 1093 1098 974 976 920 909 833 743 779 724 753 702 619 621 605 595 590 576 515 518 537 539 511 480 475 482 455 447 455 397 444 434 446 412 429 404 370 393 371 377 387 390 421 332 349 363 361 328 329 305 370 320 348 311 326 295 297 336 295 289 325 298 297 283 332 301 324 264 275 263 294 295 275 301 284 268 283 310 256 238 274 284 289 261 262 242 252 248 247 245 283 235 286 276 256 272 230 278 253 246 251 209 261 249 251 230 261 228 266 213 233 225 235 236 242 213 226 224 247 257 251 233 241 210 242 236 214 227 220 227 238 240 232 211 236 221 243 201 204 235 211 226 215 221 199 242 217 240 233 194 203 227 211 207 209 205 216 230 212 211 226 227 202 210 227 207 211 207 227 200 200 213 210 223 219 226 224 210 220 213 233 219 255 279 226 248 294 240 228 233 230 203 263 261 225 223 238 237 234 245 247 221 207 211 221 217 209 217 192 226 203 211 182 202 215 194 202 197 179 167 184 194 173 184 194 193 180 212 192 192 195 197 206 196 200 207 199 210 220 199 203 190 191 212 205 174 210 213 204 202 207 217 207 242 191 228 224 235 263 266 277 270 285 299 259 296 309 295 321 324 362 294 352 308 337 308 335 334 322 329 278 294 274 265 274 236 265 261 254 276 242 241 215 235 210 226 212 210 175 188 172 196 197 183 179 186 182 184 186 209 168 192 190 155 175 167 167 190 151 155 150 171 163 180 153 192 152 158 149 175 136 161 176 150 165 154 159 149 157 170 176 174 171 171 170 162 155 167 159 151 165 152 163 182 137 158 171 163 155 150 160 165 184 148 140 163 179 167 155 158 170 144 144 162 152 172 176 165 153 160 163 176 151 158 163 144 151 134 162 165 155 165 144 140 140 131 150 146 137 159 173 160 144 150 171 127 123 157 143 138 165 143 171 160 157 163 138 155 126 152 138 132 140 149 157 140 150 149 146 140 134 173 148 144 173 142 139 143 162 167 163 150 174 154 170 163 167 173 172 173 186 155 161 200 215 203 200 206 184 227 212 224 210 259 279 283 295 345 297 327 369 339 388 467 490 476 556 641 660 754 799 807 785 776 727 753 642 630 620 636 611 636 580 560 534 522 459 391 380 366 331 303 289 276 257 254 249 213 222 188 213 185 190 183 158 202 147 169 170 149 150 144 143 158 167 169 149 128 149 122 140 158 161 134 148 139 131 136 147 146 146 162 129 159 139 146 126 165 159 149 149 149 146 155 132 165 148 151 129 158 153 131 137 158 136 141 132 133 140 141 132 141 149 118 136 126 136 139 150 147 141 173 132 137 140 122 144 130 141 133 123 141 154 128 127 142 154 119 113 147 120 155 128 137 139 116 118 159 127 151 138 144 106 142 131 149 110 140 154 129 126 132 112 127 106 149 134 127 150 140 128 133 142 123 123 98 143 128 136 130 121 142 130 126 132 118 152 111 128 153 152 121 131 124 124 133 142 140 124 131 128 107 126 109 159 119 142 144 132 128 115 118 158 133 123 130 128 122 158 148 148 144 131 149 152 134 153 131 123 157 141 161 124 142 128 136 164 136 147 136 136 134 123 159 150 157 162 188 185 213 192 262 231 314 303 328 329 379 404 374 374 366 340 320 347 331 339 359 383 478 463 518 519 540 574 493 443 382 334 318 285 267 306 310 310 284 297 283 233 186 200 199 169 163 157 158 134 142 155 142 126 141 137 133 108 160 113 118 118 116 140 139 137 116 115 122 117 108 105 121 124 108 126 112 115 136 112 127 129 132 116 115 107 129 134 139 106 108 119 112 128 91 118 131 103 97 99 115 109 146 91 109 120 122 110 128 138 136 123 103 118 100 101 110 97 99 113 117 89 124 109 115 116 126 109 146 131 126 139 92 142 109 110 116 133 128 101 95 112 130 100 102 109 116 112 108 127 96 107 105 100 106 118 116 119 120 132 122 107 112 129 116 119 126 80 111 111 109 97 112 141 122 118 133 102 112 110 107 110 111 102 118 116 109 111 109 107 101 108 123 94 118 110 110 122 95 111 103 131 124 116 133 124 88 106 109 119 105 117 108 119 107 123 112 128 118 108 101 118 117 121 113 140 107 116 148 102 120 109 116 117 105 109 112 102 101 90 110 97 107 89 101 103 111 102 113 105 100 122 100 107 106 90 95 101 108 130 121 107 106 92 78 115 92 120 105 110 103 109 134 109 96 108 116 115 108 119 100 107 109 109 101 103 112 110 112 92 98 107 109 105 118 131 109 117 118 108 119 110 101 112 76 119 133 106 88 128 142 101 127 146 116 126 106 117 124 109 124 120 111 140 117 119 81 102 103 123 113 110 113 148 121 131 129 128 106 121 120 110 111 141 120 124 144 112 105 106 103 107 98 119 113 110 137 119 130 106 130 129 117 107 148 129 138 123 123 121 129 133 138 105 123 123 134 102 109 123 146 107 107 107 149 140 107 126 112 91 126 118 119 115 120 127 117 116 139 123 132 100 117 122 109 119 106 133 116 124 108 117 144 121 120 121 149 138 106 123 129 128 132 140 134 148 132 128 124 130 149 157 144 149 130 173 170 180 165 164 188 197 209 225 244 272 277 292 297 274 343 335 377 436 441 556 618 727 838 955 1234 1468 1794 2276 2790 3267 3589 3864 3776 3822 3562 3313 3011 2872 2674 2670 2617 2617 2532 2611 2501 2307 2200 1941 1898 1687 1512 1273 1099 988 806 744 679 560 528 444 434 365 389 316 314 261 272 264 254 220 223 189 175 169 158 150 155 161 141 144 159 147 141 152 144 118 129 130 127 115 130 139 128 106 107 132 127 122 123 118 124 123 102 124 123 116 120 108 113 123 117 117 105 88 115 108 115 130 128 102 127 106 112 120 116 127 107 113 117 119 120 103 121 129 99 112 127 115 110 96 122 130 123 129 109 129 106 127 120 112 99 101 98 120 128 101 115 116 101 105 101 120 129 118 99 105 115 105 128 107 109 122 108 113 99 115 102 88 118 120 116 110 126 88 99 123 110 88 90 102 109 131 113 117 105 101 85 117 98 113 94 102 108 97 110 101 95 84 79 100 106 118 108 103 101 85 115 106 106 117 109 103 110 102 126 98 122 96 100 105 90 108 116 97 131 82 122 119 122 108 119 112 97 119 113 98 86 131 105 94 105 103 108 99 98 106 98 105 92 115 91 116 109 94 107 118 116 105 105 108 105 77 110 107 105 105 109 112 98 129 97 94 89 90 99 79 111 101 118 111 112 113 92 97 122 98 106 112 99 94 92 101 99 94 117 103 96 101 94 108 115 111 107 99 81 109 100 112 123 101 130 110 116 105 108 113 69 97 84 120 97 98 110 101 117 113 113 113 118 117 122 147 126 139 122 133 140 141 147 137 137 128 136 139 148 157 140 143 138 152 123 131 123 134 144 137 111 124 128 140 126 133 111 124 120 106 117 97 99 119 109 120 106 110 110 126 110 94 127 119 96 97 96 106 99 95 100 92 105 112 90 88 95 110 109 91 117 103 117 121 79 124 94 103 112 107 102 100 106 107 92 109 96 105 94 123 108 122 111 115 108 100 123 89 96 99 132 102 99 119 89 105 121 112 116 112 97 110 118 111 102 115 124 123 119 118 124 146 152 124 140 143 162 129 143 131 163 141 159 173 184 183 182 243 242 283 318 332 322 343 315 373 394 446 464 537 581 572 569 554 494 511 444 459 405 345 381 336 382 350 382 415 397 337 330 293 298 249 195 209 222 165 204 192 219 178 204 179 201 171 169 175 172 154 150 148 172 143 150 164 140 118 146 138 131 134 115 115 120 129 127 128 127 110 107 126 103 121 103 107 99 102 107 113 106 101 121 101 86 100 97 98 123 99 108 106 120 126 111 122 107 89 94 90 116 100 89 121 80 120 88 120 96 97 118 95 100 103 100 89 92 110 120 87 102 86 102 100 82 113 91 110 106 88 108 100 121 88 97 88 97 100 92 103 96 108 119 129 101 113 99 105 106 84 99 88 91 110 94 105 86 89 102 92 108 87 98 105 102 107 109 97 73 112 107 96 105 105 105 98 105 87 111 82 88 102 82 74 103 103 99 100 99 77 79 89 100 102 110 119 103 90 107 87 98 86 96 96 106 105 101 88 97 101 82 103 94 88 95 84 88 105 91 90 106 79 99 75 99 85 82 107 74 98 98 101 111 79 105 94 102 88 95 89 87 105 87 80 97 82 85 82 79 96 115 109 117 102 96 87 99 119 79 94 90 81 99 84 95 87 84 105 100 96 94 80 99 90 84 101 76 106 97 90 99 98 95 98 110 103 92 88 102 80 99 99 111 82 85 99 101 111 95 79 98 82 103 98 102 103 87 85 94 95 96 122 82 97 100 100 112 87 115 97 88 100 101 98 77 98 90 87 94 105 86 95 110 96 89 99 111 107 107 77 101 94 90 94 88 82 86 98 84 101 103 94 96 90 98 110 102 113 109 90 112 92 96 84 105 96 85 75 94 95 91 101 81 119 97 92 94 90 100 77 88 88 82 97 84 107 100 101 94 96 78 100 106 98 98 99 105 105 68 91 80 86 89 89 90 89 102 74 80 95 97 94 82 91 98 84 103 92 101 92 89 82 95 94 82 109 95 117 112 86 111 96 86 113 96 90 110 99 92 96 103 102 112 103 111 106 92 107 102 102 92 108 102 119 96 97 108 97 100 102 75 103 99 101 120 103 120 99 81 115 101 109 110 107 116 100 103 90 102 85 87 91 101 85 105 98 107 110 92 122 102 92 85 85 99 99 100 95 96 94 90 89 85 108 106 106 106 101 79 102 105 103 105 128 119 126 96 117 122 136 119 127 117 112 163 146 159 173 186 179 176 190 150 185 178 169 170 199 163 179 171 164 141 164 183 172 155 137 146 160 148 143 129 153 140 126 150 117 129 127 129 99 126 120 133 117 92 118 89 117 79 120 98 119 126 95 110 102 95 117 107 110 90 116 113 108 112 119 90 100 113 113 117 106 129 122 110 107 103 98 108 117 106 132 98 100 101 102 124 120 136 105 98 126 110 115 126 95 107 119 110 108 94 124 123 127 120 126 109 110 97 118 110 122 134 105 138 115 112 127 115 148 103 150 116 139 139 120 143 146 142 164 163 173 159 164 175 153 174 179 216 185 214 258 241 284 347 332 358 373 447 422 461 454 532 534 558 547 655 686 738 702 752 778 795 786 783 728 757 753 727 722 680 633 689 592 597 561 524 532 566 549 474 471 496 409 454 398 389 350 327 328 304 290 275 253 256 242 227 270 231 243 247 265 267 255 256 274 263 311 353 329 387 435 499 527 568 655 755 848 942 1139 1284 1340 1404 1524 1393 1568 1453 1539 1441 1412 1411 1274 1175 1126 1155 1044 1058 1006 1044 1095 1085 1009 958 931 894 850 807 732 691 613 621 536 460 445 405 415 376 338 318 329 306 267 268 285 245 222 232 219 238 190 195 176 178 192 148 183 158 188 173 167 165 146 158 138 160 121 123 148 144 106 132 107 139 117 112 126 132 117 107 117 98 84 92 84 90 106 113 111 110 96 117 118 106 86 97 91 106 111 106 110 115 108 89 88 92 109 113 99 90 98 99 100 95 92 120 97 105 108 116 94 87 97 99 85 99 98 105 96 81 91 86 100 106 94 78 110 111 94 100 90 115 89 118 105 110 90 100 97 103 94 94 100 102 100 107 118 101 82 100 101 106 110 99 99 94 86 107 95 78 92 91 106 98 92 86 86 103 75 89 95 111 97 92 100 100 82 94 108 95 103 88 88 85 103 95 112 96 88 118 102 89 70 87 85 98 90 94 86 71 92 86 86 91 94 96 99 73 86 113 78 109 94 94 103 60 80 80 86 87 88 91 99 89 94 99 92 88 110 89 89 85 70 95 95 96 86 92 95 89 87 95 95 102 94 91 82 86 107 87 98 77 89 94 82 97 81 88 108 91 91 87 81 90 109 81 89 60 75 91 91 90 103 88 94 88 94 80 92 94 92 95 78 97 78 84 90 88 88 91 118 73 77 90 79 109 86 80 87 78 94 77 88 73 94 89 79 79 75 84 84 78 79 99 81 99 81 94 96 84 85 89 89 90 100 91 81 86 74 68 88 78 87 85 89 85 85 82 88 92 90 90 86 95 99 106 76 82 96 96 76 100 100 82 88 92 87 89 94 87 80 92 80 78 86 100 97 78 96 88 89 76 90 92 85 89 85 88 75 73 87 80 89 91 95 86 84 95 88 85 97 84 87 85 68 97 108 106 89 76 67 73 69 89 88 86 81 67 85 92 94 74 101 86 80 79 78 84 98 84 86 73 94 80 95 74 89 84 82 77 90 90 92 80 73 101 87 86 79 81 98 89 99 91 92 95 95 87 102 82 100 74 85 91 80 97 89 84 88 74 97 85 101 98 81 84 92 100 101 98 80 73 80 96 76 75 78 109 74 71 85 90 85 92 80 97 94 100 69 90 67 86 91 88 105 76 77 84 87 98 94 96 86 79 79 74 90 86 95 90 107 91 79 80 86 96 71 76 78 80 80 87 108 81 82 89 81 89 90 95 90 80 86 97 98 89 88 82 67 96 95 82 89 90 81 86 98 89 78 90 78 90 97 87 78 77 69 75 90 70 81 92 88 58 77 80 82 99 100 79 71 89 75 97 101 79 78 107 86 98 69 81 92 85 86 67 94 98 84 80 71 68 82 100 94 75 84 78 77 69 87 98 103 85 87 79 94 75 78 84 76 79 92 90 85 77 91 94 88 78 75 99 89 97 77 81 92 90 94 95 84 75 90 81 70 88 82 84 77 74 68 80 64 81 91 77 85 74 64 81 87 91 81 76 76 85 79 92 81 74 96 95 77 82 69 81 94 78 90 88 75 79 67 82 81 89 95 87 87 88 73 89 77 81 82 75 80 76 88 74 87 92 89 81 77 87 79 87 98 76 94 74 75 74 95 80 76 65 82 74 74 60 77 70 99 71 82 74 70 86 84 84 106 75 82 82 99 82 96 88 80 84 82 87 82 98 98 88 74 91 92 79 67 79 81 81 66 89 66 88 82 103 73 97 90 75 108 71 90 69 88 81 89 98 69 103 82 85 76 97 70 79 84 111 76 106 87 87 98 90 99 88 88 85 91 96 74 90 77 85 85 78 86 86 90 98 78 84 71 89 79 88 84 76 85 80 91 88 88 87 98 82 88 94 88 87 87 69 94 100 97 89 76 96 90 86 106 90 81 92 75 90 100 91 86 80 87 70 99 87 77 90 74 73 75 84 90 85 84 95 98 86 75 81 79 100 97 91 91 89 95 82 85 73 99 59 78 107 65 71 77 80 71 78 90 82 84 75 78 92 86 81 97 81 86 87 82 103 78 89 105 103 106 84 98 91 82 90 89 103 88 102 99 92 89 89 113 101 110 113 120 128 124 128 138 142 146 170 202 158 226 228 233 243 256 255 292 270 293 280 283 258 257 243 223 227 202 227 206 205 215 182 205 186 180 193 212 213 163 188 196 189 172 169 162 148 130 128 121 111 96 148 102 101 103 107 89 73 98 88 107 86 82 86 100 98 97 98 86 100 86 69 90 115 84 95 59 98 98 86 88 73 82 79 94 109 103 91 112 89 68 101 96 96 98 107 90 96 100 105 106 107 87 102 108 90 108 120 122 130 115 98 131 124 150 163 163 139 169 185 206 243 295 338 386 403 477 539 639 686 704 730 712 672 572 535 482 459 399 332 316 295 305 316 329 325 372 416 377 407 424 393 418 355 367 319 305 262 210 215 180 174 173 138 174 105 124 140 117 115 140 127 95 134 103 111 117 89 106 102 100 82 103 97 91 90 81 84 108 79 100 86 90 87 90 79 101 87 86 80 82 85 70 97 86 94 106 71 99 95 73 88 86 92 87 102 89 88 85 96 101 80 79 96 69 85 84 82 89 69 82 78 85 88 80 76 80 85 69 85 96 95 80 94 91 75 92 68 95 78 76 71 76 73 79 82 77 66 87 91 80 77 87 80 94 73 69 92 81 82 94 97 97 85 96 78 87 77 77 92 97 92 89 87 82 87 66 85 87 75 87 101 89 70 88 81 90 89 88 90 79 92 69 76 69 92 95 88 75 74 89 80 94 90 71 86 90 79 98 98 78 81 89 99 80 92 84 106 73 81 97 91 75 59 88 70 73 90 82 94 100 75 74 73 80 64 67 64 73 91 89 75 70 68 106 92 86 95 87 74 77 67 100 95 95 82 65 86 92 73 95 96 100 94 68 95 105 82 70 86 99 103 82 91 103 97 127 109 105 123 98 108 103 118 140 112 133 129 130 118 146 128 150 143 152 123 126 113 123 121 103 111 110 128 118 112 117 128 107 106 123 111 108 127 112 110 94 109 101 99 105 118 92 84 81 90 84 86 79 107 100 82 70 97 95 91 91 94 87 82 75 95 75 86 85 90 74 77 76 88 85 99 92 94 70 81 92 76 96 102 74 78 86 66 88 91 86 77 76 77 89 90 85 80 90 96 95 73 97 64 84 105 82 89 77 76 97 95 94 87 117 85 92 85 102 86 94 81 88 105 107 101 95 87 106 86 88 86 81 95 84 73 85 84 90 79 86 73 102 92 85 86 89 103 109 116 108 98 110 96 105 146 111 110 123 151 173 161 176 173 199 180 184 222 221 185 195 197 193 228 201 210 219 217 213 199 223 216 201 192 201 200 188 200 196 227 175 179 212 180 169 185 181 172 162 179 155 160 141 163 134 143 157 143 108 110 137 109 117 121 112 123 88 120 99 106 102 103 113 115 100 92 82 94 86 94 111 102 95 71 117 82 118 98 79 101 84 99 86 112 111 101 107 108 101 103 95 91 99 103 111 112 94 111 108 132 115 113 110 128 126 111 148 127 132 126 128 158 165 161 148 132 159 161 165 155 197 149 184 178 216 185 228 257 231 238 268 284 348 373 395 420 460 574 586 657 657 621 655 663 662 702 718 621 663 654 647 601 572 587 603 541 530 575 598 587 578 586 591 624 599 608 525 585 618 539 476 503 477 391 387 371 348 282 278 295 288 266 276 259 261 268 256 270 245 217 234 189 204 204 192 195 207 167 161 178 193 189 212 207 195 234 241 216 268 297 300 373 338 414 418 505 459 505 620 578 621 603 680 713 692 611 666 668 597 596 530 524 513 499 455 454 441 442 395 491 495 444 461 397 395 411 434 395 428 348 355 298 340 278 292 245 263 217 193 200 195 199 161 147 154 130 144 123 136 108 119 128 118 108 113 108 108 122 138 128 109 98 112 87 99 99 108 105 84 92 101 94 86 92 110 101 91 102 96 97 65 90 77 77 95 94 91 88 76 84 111 85 88 97 81 74 100 87 98 82 84 95 79 112 91 119 116 102 109 112 107 96 107 100 97 101 124 118 99 106 89 109 118 108 97 88 97 97 109 124 90 88 95 100 101 90 84 97 89 107 85 81 99 88 88 96 98 92 80 85 81 86 79 75 85 81 100 89 84 85 82 85 90 89 78 86 89 68 78 85 84 84 85 99 78 73 87 85 102 74 87 70 79 74 79 71 92 92 95 82 86 76 84 79 76 78 92 61 76 86 74 96 55 78 87 68 73 81 82 103 73 88 92 91 76 82 89 78 95 65 78 77 100 90 84 100 103 77 88 86 71 109 96 74 95 97 106 77 90 113 100 95 100 68 111 99 86 116 106 96 115 109 108 108 119 134 124 144 144 157 167 200 216 249 255 338 379 415 422 502 491 464 462 412 438 415 388 383 356 337 272 292 247 219 245 221 248 225 236 275 285 261 308 303 310 310 275 262 249 246 251 203 209 188 171 152 153 138 131 120 112 117 103 110 90 113 95 112 94 107 88 101 86 81 86 85 87 96 77 76 91 88 84 66 89 92 81 86 86 76 88 77 79 78 90 91 67 91 85 101 75 71 65 73 74 80 78 99 92 84 86 85 91 90 84 80 67 67 91 80 81 97 84 67 61 97 77 91 86 99 67 84 75 99 70 89 91 86 66 71 90 75 71 63 70 77 81 81 78 79 64 68 73 86 79 71 74 87 80 85 78 89 92 88 91 74 79 90 70 87 79 76 67 59 94 90 63 71 87 69 86 84 88 77 66 87 81 86 64 77 79 77 91 67 66 67 75 67 73 75 89 75 78 65 81 86 74 80 53 78 90 89 85 80 82 57 85 81 77 79 77 65 84 92 77 74 84 74 65 91 85 88 63 80 67 71 74 67 98 88 78 70 65 81 85 90 81 79 73 79 75 89 65 70 67 74 84 70 92 74 70 69 89 80 71 82 75 73 73 85 71 73 77 84 65 88 79 64 79 79 86 69 92 79 85 68 70 89 86 82 69 75 75 77 67 76 77 74 75 88 81 79 70 81 85 81 88 75 68 99 71 77 88 85 86 78 67 82 78 88 85 95 80 77 66 95 71 81 100 78 69 77 85 89 85 80 89 92 74 92 65 77 74 70 92 96 85 99 97 79 86 94 88 80 88 91 91 94 92 80 81 109 99 108 109 88 99 90 109 107 115 108 129 116 126 112 109 116 103 148 129 129 129 157 159 160 151 194 200 184 228 215 249 253 247 257 245 279 290 322 290 314 324 310 331 311 266 264 268 249 251 216 251 223 237 204 222 246 217 232 219 213 234 221 242 237 209 207 204 174 171 174 172 152 167 146 143 146 143 111 131 123 107 127 109 96 98 121 103 101 95 85 105 90 75 91 82 71 98 86 85 69 74 89 87 87 78 77 90 71 89 98 94 71 71 85 84 89 76 74 85 77 58 80 88 70 88 59 80 80 95 84 96 89 77 81 71 64 74 77 78 76 76 90 69 80 82 84 79 82 71 74 75 68 87 74 74 79 66 76 85 64 75 99 79 69 91 77 90 77 90 81 80 60 77 69 81 74 88 69 88 91 79 75 73 94 81 69 76 80 76 70 69 69 79 71 57 80 88 80 84 82 65 68 73 75 74 69 81 63 84 94 74 85 75 106 77 77 76 81 71 102 82 89 67 77 64 73 94 65 74 69 74 66 74 89 76 95 81 67 76 79 75 68 96 82 91 90 77 74 82 80 80 79 86 102 75 89 73 80 77 59 74 73 78 78 58 84 90 87 88 78 86 81 74 77 84 90 77 69 77 84 58 68 58 81 85 76 80 70 68 100 89 91 84 90 86 78 80 71 103 94 82 87 120 113 130 137 139 130 144 118 106 119 129 128 143 144 140 150 146 130 116 129 109 127 130 123 138 119 116 116 121 118 129 112 106 117 126 123 108 97 116 97 105 105 112 101 121 121 105 96 88 91 98 91 86 98 92 101 115 82 64 100 89 89 79 87 77 89 88 75 81 79 76 74 79 108 78 89 70 73 69 84 80 92 50 91 85 86 79 77 67 79 80 103 86 69 69 65 84 65 81 80 65 76 66 76 80 80 87 87 75 78 77 71 82 85 96 73 76 71 56 87 74 77 86 76 87 81 91 70 64 70 84 77 70 75 85 73 87 69 84 79 75 67 59 67 86 87 80 64 73 73 70 64 77 88 82 91 79 71 87 85 76 103 79 81 68 68 64 75 70 84 86 81 80 100 86 79 87 60 76 85 96 77 106 73 98 79 89 92 85 92 85 94 90 78 90 81 91 95 94 105 99 94 106 110 107 106 91 98 109 121 134 140 123 119 133 127 140 122 141 153 197 197 209 201 190 232 219 232 275 257 279 300 254 296 257 313 285 280 283 280 270 280 272 272 232 232 194 236 236 252 214 237 230 241 199 188 223 205 209 184</intensities></dataPoints></scan></xrdMeasurement></xrdMeasurements>