File: data/XRD/data/YellowSaddleDolomite_std.xrdml
<?xml version="1.0" encoding="UTF-8"?>
<xrdMeasurements xmlns="http://www.xrdml.com/XRDMeasurement/1.0" xmlns:xsi="http://www.w3.org/2001/XMLSchema-instance" xsi:schemaLocation="http://www.xrdml.com/XRDMeasurement/1.0 http://www.xrdml.com/XRDMeasurement/1.0/XRDMeasurement.xsd" status="Completed"><sample type="To be analyzed"><id></id></sample><xrdMeasurement status="Completed" measurementType="Scan"><usedWavelength intended="K-Alpha 1"><kAlpha1 unit="Angstrom">1.5405980</kAlpha1><kAlpha2 unit="Angstrom">1.5444260</kAlpha2><kBeta unit="Angstrom">1.3922500</kBeta><ratioKAlpha2KAlpha1>0.5000</ratioKAlpha2KAlpha1></usedWavelength><incidentBeamPath><radius unit="mm">240.00</radius><xRayTube id="1010041" name="PW3373/00 Cu LFF DK184033"><tension unit="kV">45</tension><current unit="mA">40</current><anodeMaterial>Cu</anodeMaterial><focus type="Line"><length unit="mm">12.0</length><width unit="mm">0.4</width><takeOffAngle unit="deg">6.0</takeOffAngle></focus></xRayTube><sollerSlit id="21010002" name="Soller 0.04 rad."><opening unit="rad">0.0400</opening></sollerSlit><mask id="22080002" name="Inc. Mask Fixed  10 mm (MPD/MRD)"><width unit="mm">6.60</width></mask><antiScatterSlit id="22010003" name="Slit Fixed 1°" xsi:type="fixedAntiScatterSlitType"><height unit="mm">1.52</height></antiScatterSlit><divergenceSlit id="22010004" name="Slit Fixed 1/2°" xsi:type="fixedDivergenceSlitType"><height unit="mm">0.76</height></divergenceSlit></incidentBeamPath><beamKnife id="29010002" name="Beam Knife for X'Celerator"/><diffractedBeamPath><radius unit="mm">240.00</radius><sollerSlit id="21010002" name="Soller 0.04 rad."><opening unit="rad">0.0400</opening></sollerSlit><filter id="20010004" name="Nickel"><material>Ni</material><thickness unit="mm">0.020</thickness></filter><detector id="7010013" name="X'Celerator" xsi:type="rtmsDetectorType"><mode>Scanning</mode><activeLength unit="deg">2.122</activeLength></detector></diffractedBeamPath><scan appendNumber="0" status="Completed" mode="Continuous" scanAxis="Gonio"><header><startTimeStamp>2009-08-17T18:48:38</startTimeStamp><endTimeStamp>2009-08-17T19:00:18</endTimeStamp><author><name>Administrator</name></author><source><applicationSoftware version="2.0">X'Pert Data Collector</applicationSoftware><instrumentControlSoftware version="1.5 ">XPERT-PRO</instrumentControlSoftware><instrumentID>0000000013030094</instrumentID></source></header><dataPoints><positions axis="2Theta" unit="deg"><startPosition>5.00417782</startPosition><endPosition>74.99932830</endPosition></positions><positions axis="Omega" unit="deg"><startPosition>2.50208891</startPosition><endPosition>37.49966415</endPosition></positions><commonCountingTime unit="seconds">10.160</commonCountingTime><intensities unit="counts">1217 1336 1300 1277 1227 1306 1323 1310 1266 1300 1224 1176 1220 1273 1211 1212 1235 1174 1208 1193 1197 1185 1211 1235 1290 1215 1201 1232 1131 1201 1228 1207 1195 1131 1137 1159 1168 1162 1239 1154 1237 1186 1199 1226 1174 1123 1199 1179 1155 1141 1119 1171 1171 1144 1142 1089 1191 1142 1118 1162 1133 1124 1155 1172 1148 1156 1065 1134 1140 1132 1118 1134 1143 1092 1150 1112 1162 1108 1016 1152 1114 1137 1170 1088 1110 1144 1080 1101 1112 1111 1075 1096 1120 1114 1087 1090 1106 1041 1076 1069 1139 1113 1053 1095 1024 1058 1114 1089 1081 1093 1122 1079 1083 1044 1107 1072 1001 1085 1040 1028 1040 943 1108 1085 1058 1072 1090 1017 1044 999 968 1016 1049 993 1051 1035 1114 1003 1030 1026 1027 1051 1033 1039 1028 1026 1051 1017 1031 1025 988 1037 1055 1040 1027 1017 988 1048 1012 1090 989 987 1004 1025 1041 997 1005 939 1038 977 962 961 1033 1078 980 1030 988 998 989 1051 1028 975 977 950 989 964 1033 997 1040 983 991 998 984 1004 870 1006 1012 976 978 962 989 1025 911 1002 1006 996 942 999 910 962 965 926 996 991 995 924 1035 985 908 929 1009 936 958 909 944 957 943 965 947 1025 962 1022 982 949 951 995 939 978 923 930 897 926 952 977 952 1028 921 982 944 965 910 966 920 951 947 966 914 935 934 947 926 952 920 904 941 1005 997 1017 936 888 870 980 922 972 952 953 918 954 898 868 879 957 899 888 879 936 899 905 900 885 868 874 902 933 964 926 972 900 964 862 961 921 976 902 872 880 940 925 950 892 932 860 922 916 955 965 903 898 906 887 915 868 928 943 812 909 910 905 824 974 954 910 910 864 876 936 949 920 862 863 897 925 954 863 903 918 931 890 845 916 863 893 883 929 901 873 888 866 877 830 903 867 870 835 929 932 829 880 893 864 807 860 867 842 841 846 893 889 892 877 862 809 890 869 939 819 877 848 889 889 874 897 835 925 905 872 831 881 851 841 857 846 767 836 824 810 824 843 835 864 851 836 840 829 807 883 871 824 853 869 843 878 840 800 852 807 764 808 810 825 827 863 858 837 818 809 825 806 827 841 817 818 817 811 765 753 816 799 818 832 847 833 868 812 824 775 860 779 828 864 799 745 828 793 830 806 862 861 807 915 815 800 862 828 879 764 822 843 793 803 805 759 831 800 806 818 786 830 790 785 821 790 817 755 809 824 788 822 820 800 775 811 851 777 774 819 717 767 769 859 790 767 798 747 783 756 773 799 759 812 799 816 772 820 754 775 770 814 776 752 770 808 765 809 786 821 773 785 742 807 738 788 790 763 738 804 770 806 808 785 827 775 757 804 755 782 775 778 733 806 798 821 720 780 752 769 784 798 702 739 762 773 789 745 756 745 768 788 726 780 749 738 686 699 742 746 730 720 760 726 728 768 735 718 735 732 756 760 782 714 736 801 709 726 699 777 773 743 734 696 785 757 705 786 710 758 732 832 739 773 778 748 791 756 850 744 735 803 776 745 751 751 700 717 714 671 737 694 810 709 734 692 681 709 741 716 713 693 723 755 691 738 738 742 675 714 807 704 716 693 703 724 741 659 693 704 707 744 718 668 751 709 733 702 696 739 663 714 689 714 713 732 683 766 785 674 727 711 753 730 710 674 731 651 727 707 756 753 704 692 715 712 724 718 733 703 671 712 649 671 723 682 700 680 712 699 699 706 637 711 696 643 689 716 694 627 699 721 710 720 684 709 712 678 691 704 668 679 633 649 679 650 670 679 690 711 713 684 676 651 733 679 704 653 640 715 673 678 649 660 650 637 696 660 643 726 703 668 674 683 644 668 687 661 717 683 654 640 684 684 660 623 669 654 631 695 687 664 701 657 659 655 623 660 689 620 700 702 632 674 720 691 692 674 669 647 629 622 654 684 685 695 616 651 649 658 626 659 661 657 623 632 664 632 709 641 674 648 650 614 655 617 631 618 683 706 649 664 701 666 637 620 628 682 661 714 647 669 660 664 660 611 651 601 622 600 627 624 632 630 640 643 669 683 619 672 663 644 661 623 622 612 616 647 641 611 659 669 586 638 629 623 691 614 579 621 631 649 619 628 588 642 641 617 640 627 619 636 644 655 578 602 636 601 607 609 653 588 590 586 622 585 632 627 642 577 590 586 597 602 585 598 627 619 629 628 619 617 629 605 621 574 553 565 619 599 577 601 597 647 569 586 614 574 627 574 560 595 613 611 668 607 633 642 575 574 580 600 606 628 643 584 553 559 596 554 591 565 584 582 593 600 608 600 617 591 568 554 585 563 611 563 568 543 560 566 613 544 612 652 539 569 582 550 578 601 557 563 540 572 565 595 585 560 598 575 579 596 589 561 533 555 524 603 547 541 554 595 580 541 540 563 515 522 515 570 550 532 565 548 558 567 566 526 525 522 533 536 524 543 554 538 540 517 556 519 505 544 534 525 495 536 577 533 526 544 543 547 505 558 518 546 576 567 570 550 567 577 570 515 556 511 522 549 559 543 550 577 504 544 568 565 527 528 534 496 533 566 506 555 529 536 535 511 509 519 477 501 495 517 502 525 518 491 519 533 527 546 530 577 480 503 518 550 523 551 492 504 532 543 478 484 506 490 538 487 550 485 517 517 466 492 497 534 522 532 515 513 468 508 513 535 503 499 511 543 481 503 506 532 505 465 494 498 483 487 431 505 462 478 490 501 483 463 470 476 494 463 476 504 481 505 494 478 450 463 488 496 432 495 474 465 476 470 515 495 471 471 464 439 424 468 435 505 422 490 468 444 494 502 512 484 465 483 481 495 466 488 463 470 455 512 480 497 444 421 434 468 484 487 466 422 411 425 485 492 452 424 462 459 419 449 465 432 465 425 400 477 423 429 462 449 455 477 439 438 452 462 439 444 461 474 416 435 470 425 445 463 441 464 445 460 446 449 432 414 431 398 423 446 452 442 422 447 425 425 415 399 412 408 395 407 428 428 435 431 416 399 415 444 443 440 372 415 423 439 419 390 394 413 449 409 403 371 428 428 423 419 410 397 426 408 367 452 426 409 392 395 382 380 433 419 395 386 398 397 370 402 390 429 362 398 403 408 371 405 395 400 399 353 377 347 434 416 428 365 368 409 379 410 373 383 390 369 390 362 408 357 443 372 365 392 399 372 405 390 421 398 416 412 358 386 350 376 392 351 380 376 343 390 403 391 346 378 379 356 428 376 376 393 391 403 384 379 376 368 365 369 378 374 367 394 339 350 363 351 343 357 351 390 384 367 393 341 337 318 356 356 327 368 347 376 376 363 334 342 356 368 368 336 367 331 341 377 368 330 322 308 304 362 366 331 334 352 370 342 336 335 345 341 349 357 343 322 361 353 321 307 342 342 315 321 342 341 334 329 345 337 316 322 319 322 338 288 319 315 311 276 324 336 352 313 347 313 315 287 295 297 324 305 341 338 317 318 324 347 317 355 311 287 287 357 343 320 320 296 288 341 308 308 306 331 338 284 300 349 301 287 313 319 301 293 306 295 304 316 299 289 317 293 328 280 297 266 299 329 327 303 303 315 292 319 290 298 310 306 308 306 279 295 270 272 324 288 314 324 267 273 293 272 268 293 295 296 240 263 306 280 286 285 280 265 252 257 288 304 267 284 299 276 276 267 266 238 288 294 269 293 261 266 284 273 274 274 285 296 252 265 285 272 263 295 294 282 284 265 317 276 254 314 266 308 274 249 278 262 263 278 253 283 299 283 267 286 298 266 256 263 264 255 310 274 290 296 265 279 278 258 256 257 258 268 234 261 257 269 257 240 263 267 247 253 278 246 285 265 246 267 257 273 269 249 226 263 272 280 266 257 298 259 225 237 252 265 236 254 262 267 235 242 259 237 216 246 277 257 246 258 238 235 253 224 259 258 228 235 263 275 252 262 253 270 264 238 252 248 251 259 249 230 258 216 257 242 244 231 228 242 204 220 259 261 230 253 261 220 247 211 225 265 244 219 233 232 225 236 243 233 226 253 236 249 267 242 192 220 258 264 226 230 241 236 249 226 217 255 243 222 243 258 225 225 237 235 233 230 267 214 233 251 234 223 226 248 207 235 212 201 225 245 227 225 183 216 220 227 206 249 234 231 200 215 224 225 211 219 233 256 216 207 220 244 243 216 248 231 223 238 237 221 252 212 233 219 217 215 205 228 233 206 257 214 205 224 243 213 216 206 212 197 202 196 210 225 221 231 211 238 205 215 241 210 221 195 223 207 216 224 220 203 230 205 231 211 194 254 211 214 233 232 213 217 215 213 204 227 221 212 240 221 206 206 210 201 209 199 203 224 197 222 232 200 211 189 211 190 221 246 203 242 251 191 181 209 189 234 246 190 203 221 221 214 192 223 212 207 214 200 179 216 195 222 207 219 226 201 221 183 185 158 217 214 203 214 196 222 213 210 216 227 191 193 210 226 207 220 234 206 203 211 221 200 192 219 212 213 222 196 206 207 203 188 184 213 165 222 216 209 176 203 216 226 191 207 189 202 219 185 212 176 196 233 200 225 178 175 205 175 211 186 203 193 223 206 191 191 199 182 184 202 194 202 179 158 178 173 210 185 184 181 189 183 220 203 202 192 204 212 194 173 200 216 204 183 228 200 202 197 191 206 172 193 190 195 200 193 220 191 197 207 213 189 243 202 219 216 258 220 221 213 225 209 240 216 207 244 235 261 251 279 274 276 256 283 288 251 242 265 226 255 244 206 217 178 216 179 182 197 170 201 195 211 189 194 161 184 205 200 212 180 197 174 180 206 191 188 165 205 173 189 194 170 212 161 175 189 188 185 180 161 173 180 210 173 190 189 171 169 171 181 211 179 189 168 189 181 169 160 155 171 171 178 197 195 158 151 162 184 180 175 178 158 179 194 182 174 169 159 179 173 157 179 186 158 211 161 155 184 181 194 183 181 182 176 188 167 215 195 182 175 179 190 175 162 169 154 130 188 163 171 163 160 188 168 171 184 158 191 174 167 173 180 155 169 169 170 161 178 172 181 160 151 184 169 160 171 173 183 161 152 169 170 162 167 167 164 168 163 152 185 160 190 190 148 179 154 148 157 148 159 188 184 140 154 160 185 155 146 165 180 176 159 173 159 179 147 181 162 186 167 163 165 164 141 176 133 161 181 179 172 128 186 167 161 164 182 150 165 159 174 171 176 190 183 199 182 190 163 167 164 168 169 203 153 172 174 178 185 192 197 205 176 216 200 235 202 237 254 308 259 348 337 376 383 408 360 342 307 275 285 275 263 255 232 234 214 220 204 175 189 162 160 151 172 152 186 180 189 167 157 158 161 171 164 155 163 149 151 174 179 144 153 128 149 172 140 168 155 165 126 143 173 138 153 141 140 154 168 157 159 170 144 150 149 148 153 164 159 154 153 151 151 168 140 151 143 149 161 201 172 182 133 149 150 144 159 146 152 157 147 158 146 173 137 155 140 140 151 154 168 140 154 172 157 143 140 148 144 160 157 163 154 141 153 148 154 153 162 150 132 168 174 157 143 143 127 140 137 161 143 149 157 154 167 152 118 176 122 152 179 155 157 155 168 161 160 149 163 131 150 120 132 154 162 152 173 147 153 167 147 137 137 175 139 152 146 154 155 149 143 139 158 134 154 144 154 144 168 153 162 133 141 155 162 173 175 151 158 163 139 143 160 152 146 140 140 164 140 185 140 176 147 140 147 148 140 168 120 146 136 151 171 140 122 141 159 148 127 150 142 152 144 129 153 133 137 144 133 173 142 152 144 137 151 157 164 144 155 151 170 142 154 148 153 153 171 163 160 160 150 142 147 138 144 132 140 151 152 121 144 144 147 144 143 133 140 149 150 153 100 148 124 147 151 128 124 159 129 124 155 129 149 138 147 124 160 154 168 138 163 120 134 149 154 154 127 130 158 162 158 142 143 163 148 143 162 148 151 143 131 136 146 154 138 188 147 151 160 139 161 144 127 151 139 136 146 139 141 151 164 160 128 154 132 150 141 146 121 133 165 141 149 152 131 159 126 133 154 126 151 137 151 153 143 146 123 141 138 130 147 150 142 119 108 127 129 152 129 127 141 174 147 152 128 129 149 129 144 179 144 136 143 150 155 151 140 139 165 134 142 140 136 138 148 153 140 143 150 153 153 160 142 148 138 148 142 118 116 136 152 146 120 130 147 147 165 148 137 139 148 155 150 141 160 169 144 155 167 146 154 158 181 149 128 134 150 143 186 147 137 150 158 157 150 152 159 149 179 151 180 200 199 215 191 221 222 228 196 182 167 210 193 178 170 167 185 152 172 170 155 159 143 164 167 157 164 167 147 134 149 160 147 147 146 153 133 161 136 150 139 153 147 150 129 137 162 144 160 165 158 136 151 136 127 179 168 130 164 150 174 178 147 128 144 159 151 143 136 147 141 142 157 142 154 169 152 149 141 130 147 137 129 155 129 161 134 172 146 137 178 126 140 154 139 148 130 158 137 141 129 147 141 122 131 141 150 137 126 131 151 146 151 142 140 142 120 141 128 144 157 150 160 132 142 154 133 143 149 132 128 153 141 146 144 151 143 152 146 118 124 147 149 143 151 132 154 150 131 128 133 147 164 154 146 134 140 151 136 144 144 151 149 107 161 139 154 150 151 160 123 138 134 137 155 121 147 162 159 138 164 171 180 154 169 170 171 154 155 203 155 142 162 154 165 161 167 184 163 154 140 158 147 184 151 178 160 175 168 180 188 167 197 179 176 201 173 199 175 204 188 168 196 173 149 188 197 168 165 172 146 154 157 161 154 169 170 210 194 157 195 195 188 235 212 227 206 233 230 249 248 231 224 222 207 194 221 237 233 247 234 258 225 205 231 224 206 235 274 224 214 195 221 220 201 220 206 253 244 236 215 246 252 245 227 241 245 241 235 213 234 223 255 261 253 234 214 259 240 244 228 252 242 242 264 265 235 261 222 259 273 282 290 245 272 247 295 300 301 309 353 347 395 401 412 465 528 568 655 663 773 766 895 942 972 1045 1086 1064 1161 1159 1214 1234 1310 1366 1343 1395 1439 1468 1427 1448 1642 1695 1731 1797 1888 2124 2267 2361 2670 2873 3259 3818 4604 5982 7358 9193 11288 13874 16183 18610 20088 20052 18830 16894 15303 14459 14475 14930 15349 15858 15219 13747 11784 9908 8355 6948 6069 5609 5018 4331 3898 3322 2635 2289 1936 1712 1439 1212 1068 977 849 741 632 595 563 567 476 441 451 433 379 370 327 335 324 301 283 296 256 288 264 264 267 273 232 236 227 236 232 227 220 210 195 210 240 212 238 202 206 195 185 186 202 171 173 194 197 206 176 179 216 195 201 205 160 200 186 211 197 194 205 179 192 182 193 173 179 191 160 151 182 185 169 176 186 181 158 192 165 162 183 181 161 172 189 154 194 159 165 181 150 162 175 158 164 189 140 153 158 155 155 176 175 169 169 158 155 160 161 174 147 172 159 162 128 158 171 151 162 170 175 157 147 149 137 148 154 171 140 153 155 143 171 146 158 140 161 159 143 159 140 113 147 137 158 150 163 140 173 139 140 170 141 126 132 124 176 131 151 155 159 149 144 154 161 141 134 148 151 163 146 155 165 136 162 157 157 168 143 139 148 167 161 136 127 140 165 151 169 162 160 176 175 178 181 183 215 203 214 225 214 215 232 242 244 242 242 255 226 240 200 178 176 191 221 180 165 167 140 176 163 167 150 158 168 139 162 124 138 121 151 128 142 158 137 144 131 134 124 140 148 158 159 143 129 148 134 165 153 117 139 126 138 142 148 155 147 152 182 138 165 143 173 157 183 180 178 199 214 184 178 213 210 216 223 240 270 301 308 402 453 412 431 445 359 403 420 453 505 537 561 523 496 520 453 452 397 366 345 304 297 325 325 300 284 279 242 197 190 210 175 158 152 144 153 149 148 158 139 128 137 157 143 130 124 136 142 138 136 128 101 126 130 116 129 150 127 126 129 127 118 140 149 121 139 133 126 134 124 149 142 138 128 118 132 113 117 131 118 131 122 158 130 140 129 131 151 143 122 117 129 132 139 106 113 117 123 115 140 111 117 131 128 108 119 138 113 123 140 130 111 127 131 122 121 101 115 119 121 105 102 128 105 109 109 118 131 122 124 129 124 110 109 121 100 122 113 124 107 120 110 115 109 119 108 128 106 137 111 133 115 110 144 122 128 96 124 120 109 120 118 119 120 131 117 108 130 143 98 109 137 119 102 140 142 103 126 116 120 105 101 132 86 137 119 124 129 115 126 134 110 122 124 140 97 133 116 142 133 146 140 138 138 174 160 151 167 170 180 185 214 235 256 293 329 357 358 444 400 434 420 401 408 376 388 327 356 315 338 278 286 282 261 224 237 215 191 176 122 154 136 134 146 144 116 131 102 106 136 118 103 102 95 126 133 110 136 134 116 121 116 107 110 105 109 112 120 121 133 103 108 136 105 106 107 117 110 111 90 99 112 123 105 112 112 119 105 108 91 106 97 112 112 105 136 107 132 103 100 113 111 126 115 101 119 120 98 108 123 106 116 119 130 117 115 149 113 111 113 106 102 91 124 107 82 103 117 115 117 137 106 112 97 126 123 131 111 113 124 119 120 120 96 109 123 105 110 96 112 108 123 117 106 112 110 113 121 110 109 143 128 106 101 105 101 106 108 106 112 103 119 107 99 124 92 118 113 108 131 105 124 119 111 113 126 120 118 111 124 118 106 121 112 107 108 120 115 100 102 89 96 126 116 91 105 105 91 100 124 103 115 126 122 126 106 118 111 106 109 137 116 143 140 137 137 129 134 126 142 128 119 138 142 130 131 144 138 161 116 143 146 151 146 143 152 178 167 194 204 189 205 212 180 186 233 254 275 256 274 311 353 386 460 578 679 858 997 1144 1226 1149 1074 916 720 609 525 502 549 603 618 650 655 612 544 434 356 295 214 181 165 139 146 149 118 138 133 140 119 90 103 107 133 118 144 118 111 108 103 100 103 115 110 118 129 116 97 108 139 101 94 106 109 100 100 97 99 110 95 117 107 109 129 112 86 133 80 111 116 102 109 105 98 94 111 102 79 94 90 101 110 101 110 96 87 98 87 95 99 90 97 108 103 90 100 98 106 107 111 103 110 103 89 94 121 118 84 113 103 106 106 98 105 89 105 99 103 96 91 98 78 96 97 84 98 91 95 98 100 89 106 100 82 123 96 80 102 98 96 90 105 99 109 112 95 103 75 92 88 97 88 89 103 108 91 109 89 88 95 103 90 96 87 92 91 87 87 89 86 85 96 89 106 88 98 117 118 101 106 100 100 103 85 106 80 98 70 105 85 90 94 87 91 111 92 107 81 95 88 113 89 89 108 97 103 92 116 87 105 89 105 105 81 103 88 111 91 87 113 99 82 90 106 97 100 84 90 96 91 90 112 110 87 122 91 78 103 67 91 99 107 118 117 100 89 101 96 97 107 108 84 92 95 94 90 103 98 96 89 91 91 101 99 106 98 98 106 81 107 80 92 111 112 101 100 89 122 101 91 111 99 112 103 117 100 99 109 109 99 100 100 96 97 88 120 98 108 124 108 94 120 121 99 99 97 107 101 111 120 120 109 99 112 118 124 116 120 108 103 113 109 113 98 98 108 118 120 85 115 103 86 115 102 107 119 108 105 101 116 100 101 95 134 115 107 111 113 111 98 111 101 115 147 81 126 105 106 121 101 124 120 120 100 105 118 117 119 103 108 101 108 109 102 107 102 126 108 139 127 117 128 84 102 88 111 113 98 129 120 108 101 107 103 121 113 129 157 122 140 142 121 143 160 128 152 139 160 137 140 167 189 201 200 215 237 235 276 257 274 265 288 290 325 367 314 351 379 429 397 441 468 487 525 558 638 734 837 1061 1253 1675 2024 2608 3112 3817 4547 5493 5967 6458 6659 6456 5854 4936 4091 3382 2995 2764 2862 3032 3140 3290 3510 3447 3191 2725 2316 1931 1360 1008 769 608 498 414 399 318 274 293 236 220 212 204 183 157 159 167 158 152 163 144 127 129 148 124 120 129 121 121 121 129 107 142 120 117 140 111 115 115 108 128 92 126 102 129 107 98 103 126 118 95 92 106 105 98 101 103 108 108 113 97 101 100 107 111 101 89 92 95 92 106 106 99 112 84 112 120 90 115 99 112 117 73 98 103 100 105 118 89 85 97 105 141 90 106 116 112 101 68 110 80 94 101 98 102 110 102 105 90 91 116 92 112 96 87 86 92 90 117 89 108 89 85 89 102 90 90 106 85 97 100 87 99 89 100 92 105 129 112 111 88 89 97 87 107 85 98 92 85 108 85 103 86 116 89 85 109 100 92 102 97 94 105 128 107 77 79 82 106 103 124 103 105 101 98 107 112 74 99 98 81 94 89 103 103 91 112 90 95 96 130 95 97 88 82 97 96 109 85 112 91 105 106 85 90 86 94 113 87 86 100 89 91 82 92 97 103 96 101 98 86 91 99 99 82 78 94 108 70 113 91 87 73 107 90 110 94 86 99 89 94 91 81 86 96 102 79 87 86 98 90 103 98 89 110 97 92 101 85 86 107 90 108 94 109 69 94 112 92 99 88 121 89 102 94 95 94 95 89 100 80 105 106 103 115 106 124 133 123 134 134 130 157 157 168 147 144 130 178 137 157 147 168 169 160 147 175 164 158 146 153 133 140 154 127 127 146 134 132 115 123 119 127 144 122 115 91 124 90 99 108 110 88 101 92 94 92 94 97 97 95 106 100 100 98 86 118 94 79 95 71 95 85 102 79 78 77 94 67 95 101 100 100 98 90 121 99 71 103 82 92 78 82 85 78 89 101 94 85 98 103 89 84 103 80 99 108 101 108 108 95 98 111 86 89 99 101 107 107 106 126 111 108 110 124 124 126 123 123 127 144 147 150 140 142 141 154 136 124 155 201 174 226 185 249 270 319 398 444 535 638 742 863 971 984 1068 1014 904 785 693 619 563 505 468 540 516 553 600 559 630 550 539 478 394 361 304 262 227 210 228 173 203 213 202 189 217 193 199 193 181 159 170 136 172 147 134 143 160 147 143 131 133 128 154 130 134 126 106 120 131 113 113 118 94 122 107 107 112 91 99 117 89 80 90 81 81 95 85 92 94 102 102 85 107 92 96 94 77 86 84 81 65 123 70 105 79 98 94 82 84 99 98 99 90 91 89 78 94 80 86 101 76 107 97 95 90 94 101 81 102 96 88 116 94 99 101 91 109 87 79 90 87 92 73 85 82 92 97 88 74 80 84 80 88 96 88 85 84 96 90 85 88 95 82 86 86 80 67 86 73 82 108 107 79 92 88 79 92 82 87 98 81 91 89 90 84 79 81 91 88 88 87 100 80 80 98 74 82 95 69 82 75 77 95 96 95 77 88 87 80 76 106 95 85 73 77 68 95 86 81 99 77 89 97 82 95 80 89 70 86 90 106 100 88 84 80 74 82 94 86 88 99 81 76 80 85 86 78 90 87 95 98 97 88 95 71 89 81 80 82 70 80 70 81 69 88 91 87 69 94 108 90 81 102 86 76 100 74 92 94 90 87 85 77 65 74 76 71 99 86 70 81 79 75 82 73 78 70 82 81 88 91 105 87 88 96 97 80 81 66 91 76 89 75 77 86 87 65 95 89 98 82 84 96 82 108 68 94 77 88 81 92 76 87 73 94 91 92 113 91 91 79 69 70 94 89 90 81 71 105 80 84 76 77 74 78 78 84 89 81 79 87 80 82 80 59 76 112 87 68 84 89 68 74 61 74 81 67 65 77 88 88 63 84 95 95 69 91 76 97 65 85 84 99 75 85 73 89 75 87 108 80 99 63 81 84 85 82 87 80 85 81 95 88 67 96 75 80 89 78 78 68 81 81 76 80 68 77 87 74 78 81 102 76 84 87 79 84 76 67 66 100 76 82 65 76 84 85 90 86 90 81 91 87 79 90 94 89 91 79 78 80 81 75 94 89 95 98 82 90 87 92 82 85 81 79 101 96 87 84 85 88 97 88 88 94 103 82 106 91 88 100 79 89 92 89 95 88 107 98 84 92 95 87 80 97 92 96 99 122 96 86 107 97 98 99 108 107 103 107 107 124 149 117 140 142 191 159 200 200 233 191 203 225 216 205 191 226 179 171 153 179 161 211 175 172 185 182 182 176 149 189 155 127 148 134 120 122 107 121 117 110 118 113 89 101 99 92 90 107 91 98 84 90 82 103 120 91 88 108 97 89 108 84 91 98 97 105 113 100 101 101 97 96 94 99 89 78 89 99 76 67 101 94 101 98 100 106 101 107 107 110 106 98 103 101 105 106 108 108 91 107 113 96 116 99 113 107 112 107 92 103 127 98 132 117 137 102 101 122 103 121 94 139 143 141 154 151 158 153 146 167 171 151 195 180 186 190 184 210 226 214 233 234 246 284 285 319 290 320 386 401 463 543 560 627 754 833 964 1120 1247 1521 1756 2155 2346 2695 3120 3265 3399 3483 3347 3177 2863 2454 2208 1945 1627 1555 1543 1525 1552 1680 1905 1946 1900 1944 1810 1669 1569 1321 1132 918 788 701 544 503 414 358 377 319 335 307 298 274 285 300 247 263 270 238 269 267 293 314 322 317 355 367 371 408 445 520 626 702 753 850 824 945 1053 1108 1116 1225 1126 1156 1184 1164 1121 1099 1019 1003 989 890 867 901 861 797 756 764 748 727 745 733 620 659 587 567 492 441 405 391 340 274 286 278 221 232 201 183 162 191 149 151 133 140 138 140 142 127 124 122 131 119 117 119 96 110 105 111 100 88 89 109 132 82 91 105 110 95 97 86 84 81 101 102 77 80 107 89 92 106 116 85 81 88 106 98 87 85 76 79 78 91 84 88 90 81 98 82 89 89 71 79 80 78 79 69 97 73 84 94 101 98 86 99 75 97 91 80 101 96 109 76 78 76 87 88 76 90 78 84 96 89 97 96 88 89 79 79 86 67 70 71 95 71 82 101 92 95 90 101 79 96 85 112 101 100 105 101 102 99 98 95 88 87 116 84 82 73 78 91 80 96 85 66 80 87 99 89 79 94 78 99 66 89 80 79 88 69 74 87 76 80 90 95 66 92 70 89 71 81 94 86 88 79 78 88 82 84 103 78 81 69 86 80 74 61 74 86 69 74 71 63 87 59 70 74 78 74 85 80 88 85 100 80 86 88 67 98 87 80 67 68 66 78 82 81 76 85 84 106 79 82 64 100 77 88 90 75 69 66 90 76 78 79 89 76 78 78 87 76 85 82 87 81 87 64 86 86 90 70 91 82 81 85 75 86 88 80 70 74 73 85 70 80 69 67 74 71 96 64 74 84 84 80 74 78 78 80 89 78 68 70 88 80 81 66 74 67 76 71 81 77 65 68 64 73 75 76 73 53 71 67 82 69 68 64 98 80 71 66 59 80 97 82 80 81 80 71 78 85 64 73 70 64 65 73 70 59 86 67 59 71 70 65 79 69 61 78 73 67 81 79 82 61 63 71 64 84 65 74 56 65 87 57 86 73 84 69 69 65 84 77 77 57 79 71 69 85 88 68 75 67 78 80 66 71 61 85 87 75 76 91 76 71 73 70 70 77 81 71 88 65 71 68 66 73 61 70 66 69 88 86 77 70 64 64 74 85 57 81 78 77 64 69 75 77 67 67 63 78 80 59 75 63 70 74 75 85 84 84 80 84 67 80 69 85 66 88 85 92 73 73 59 94 63 84 76 78 88 85 80 91 90 63 95 78 60 71 85 60 67 74 76 84 75 75 69 82 79 71 75 86 68 71 75 56 58 85 60 73 57 64 76 67 63 58 81 56 65 84 73 65 80 65 78 63 82 65 60 68 60 63 84 70 76 65 67 65 75 76 78 79 67 89 54 97 73 71 53 61 76 66 65 68 75 77 60 79 65 77 57 70 85 82 78 70 67 67 77 75 65 73 67 58 79 71 86 73 85 76 59 79 76 71 65 68 63 58 91 65 77 58 80 70 77 64 78 59 56 68 55 64 67 63 56 61 61 82 80 70 64 63 76 73 78 78 78 61 69 76 77 70 67 70 50 63 77 71 70 86 85 68 71 74 57 61 68 71 67 65 77 70 59 67 75 66 67 58 77 87 66 71 80 58 78 58 66 84 80 71 78 75 85 48 63 79 60 56 80 60 76 77 61 74 71 69 80 77 71 80 76 70 76 69 59 87 66 56 63 68 60 70 71 76 73 67 80 86 66 51 75 54 64 76 76 77 73 60 68 73 76 74 66 80 60 63 68 61 77 60 68 63 61 49 69 54 78 60 84 75 75 73 63 56 74 53 63 63 65 68 56 57 65 67 70 66 73 56 66 79 80 70 66 77 75 74 58 65 71 59 75 63 58 59 68 65 59 53 78 69 61 57 57 71 70 49 67 63 78 58 79 69 75 71 69 77 64 66 67 82 71 80 77 71 60 58 73 63 68 61 55 77 68 63 79 60 70 55 76 71 56 55 64 66 70 71 68 65 73 74 70 75 87 69 66 65 67 68 65 77 61 82 63 76 66 75 56 60 74 64 66 65 65 73 68 59 77 59 75 53 71 65 64 74 61 63 67 65 73 61 64 59 74 63 66 58 56 60 71 73 79 70 76 64 59 70 60 61 71 74 66 74 57 71 58 58 61 65 75 69 68 57 69 78 75 69 74 63 71 61 91 69 84 74 78 63 73 63 67 80 71 82 77 66 79 79 82 71 89 87 91 90 99 88 90 105 108 101 119 129 149 159 152 189 206 228 228 233 185 192 188 190 181 132 139 141 134 136 136 109 107 131 144 147 134 126 120 128 126 127 123 108 115 110 100 86 88 96 68 79 73 82 81 74 82 77 88 75 68 69 91 70 76 51 51 82 73 84 66 80 66 71 65 67 77 73 69 58 56 81 85 76 60 66 74 82 74 91 71 78 80 79 79 87 82 81 101 80 101 96 96 99 89 88 95 97 95 95 105 123 137 118 146 134 149 165 212 268 270 324 387 425 467 487 508 512 519 574 505 473 450 370 329 300 283 280 272 254 243 272 294 273 308 288 348 315 309 307 324 276 273 245 192 199 175 146 163 117 123 105 85 94 91 86 91 98 85 85 103 61 94 87 70 88 86 86 79 64 80 68 68 77 66 65 69 66 57 69 59 55 69 63 59 58 74 59 73 88 73 67 64 68 66 65 64 60 82 57 78 67 71 56 75 55 70 49 71 58 63 66 69 48 56 56 69 70 66 79 65 76 74 56 71 66 65 63 70 55 59 58 53 57 75 55 81 70 49 80 60 61 45 69 57 73 65 53 81 65 66 61 67 71 68 54 71 66 67 67 56 74 57 54 71 71 56 67 81 58 64 50 63 79 68 54 60 44 74 59 70 65 54 64 74 75 53 68 63 67 57 63 48 61 47 61 60 64 68 49 50 57 56 61 58 74 67 61 59 69 50 65 74 61 57 64 69 64 81 54 67 61 66 63 57 49 63 70 82 58 60 79 61 76 58 78 44 68 50 61 63 79 70 65 64 76 65 60 66 45 71 79 71 80 80 63 68 77 76 65 58 67 71 78 77 69 98 68 76 79 90 95 86 105 106 100 86 119 87 137 123 140 149 165 132 138 142 121 133 129 118 119 111 138 130 96 91 107 108 105 103 122 119 129 102 110 108 107 101 86 99 74 96 76 86 97 69 81 71 78 65 80 71 78 78 54 65 63 59 64 71 65 59 50 60 60 70 50 67 80 61 90 66 60 68 63 70 64 75 74 75 67 69 68 57 77 75 63 59 70 55 54 67 68 70 70 81 69 69 57 70 59 66 56 50 56 44 53 74 71 84 70 67 64 66 81 70 51 76 58 89 63 73 66 60 63 70 68 79 60 73 76 87 70 55 68 68 70 71 65 80 74 69 68 56 74 67 84 65 69 85 77 82 80 78 77 85 75 91 80 89 79 127 94 111 111 110 103 126 116 132 169 181 186 211 223 232 283 350 316 369 363 362 357 355 374 346 330 309 277 243 214 217 203 160 171 169 191 199 178 186 243 233 246 233 213 243 201 172 181 181 116 132 112 117 120 89 98 73 110 101 88 97 71 70 73 80 59 74 67 68 85 59 81 88 70 88 73 69 66 73 84 61 70 70 68 73 70 76 68 66 57 69 78 78 78 66 63 84 68 70 60 59 56 86 60 85 65 65 92 84 85 73 89 58 79 75 76 86 80 89 88 92 65 82 60 79 80 90 106 110 120 103 101 129 147 155 165 214 197 191 186 209 246 207 219 249 247 255 305 258 285 235 288 287 262 255 234 216 194 223 219 192 190 199 189 154 182 170 200 180 173 163 175 165 183 148 154 186 138 124 129 120 99 112 86 99 102 106 85 87 80 87 89 87 94 87 82 94 79 105 90 68 90 71 67 97 100 85 98 98 101 108 113 119 137 139 160 167 197 182 196 216 207 203 195 241 242 242 248 238 235 248 203 213 221 205 171 199 195 164 174 149 169 149 143 155 162 164 159 170 180 152 139 121 139 115 121 122 113 120 105 99 105 87 67 94 101 73 71 56 88 86 78 75 76 71 74 76 73 67 77 61 75 60 61 50 68 69 69 98 67 66 78 89 66 67 75 60 61 74 63 63 67 79 69 67 54 57 67 67 73 70 80 78 67 85 79 67 81 81 76 89 86 71 88 128 108 117 110 129 133 123 152 176 195 183 184 222 234 233 227 227 257 248 217 202 176 178 153 157 131 150 182 124 141 162 155 137 123 147 128 142 130 160 183 142 133 138 136 100 103 99 75 101 89 94 79 75 97 82 69 75 76 75 96 55 75 87 78 57 74 69 71 70 54 74 88 70 66 74 69 81 78 68 64 57 63 74 78 71 68 70 68 66 73 53 63 68 66 53 58 71 69 64 66 70 58 71 73 77 65 66 59 82 59 58 91 57 86 71 71 80 74 68 68 73 85 73 64 76 74 94 60 91 87 103 73 81 85 87 84 84 96 92 96 81 81 115 89 105 94 100 108 120 111 115 136 119 149 155 168 210 230 286 319 370 450 606 673 789 895 929 1019 1009 997 901 843 758 630 587 502 451 345 367 321 303 296 299 311 341 371 442 447 484 516 539 561 518 518 473 409 324 286 307 265 190 181 173 128 138 121 128 105 106 108 79 98 80 84 73 92 90 87 85 81 69 98 69 63 67 80 80 77 63 57 64 56 71 76 60 55 78 56 40 58 70 59 69 60 51 59 69 67 50 73 59 66 61 75 66 70 78 61 73 67 69 67 67 64 58 58 82 56 66 64 68 71 68 70 68 71 61 57 77 61 61 64 64 56 77 54 65 64 60 64 60 68 70 75 69 79 70 59 80 53 73 58 66 49 59 69 77 61 60 61 59 64 75 68 57 56 57 59 71 63 57 66 70 60 65 68 53 67 54 77 65 48 63 65 60 66 58 58 54 81 68 59 68 54 53 59 49 54 53 50 67 57 65 58 73 59 48 69 67 54 57 69 71 49 61 55 50 74 57 67 56 64 66 64 69 70 50 66 49 61 54 64 65 57 77 59 71 60 45 54 57 44 70 55 85 64 49 66 64 65 58 67 66 81 58 51 80 66 68 66 44 56 46 55 60 58 60 56 66 71 67 65 65 67 63 58 68 53 68 58 61 73 66 53 59 76 51 65 76 69 38 63 77 60 55 56 63 48 67 61 59 58 51 55 64 68 57 59 73 54 67 74 46 43 55 70 61 64 69 49 60 70 75 61 74 81 70 76 68 67 56 77 67 64 53 57 65 67 70 78 58 56 71 79 73 71 74 60 73 66 88 55 57 73 66 67 84 69 76 69 61 74 59 65 71 65 71 71 81 84 80 76 75 82 81 82 70 96 78 113 105 111 124 132 146 134 137 141 172 159 173 173 148 141 174 141 133 149 133 117 117 115 101 123 120 123 120 100 99 123 119 107 109 123 110 120 112 124 117 113 107 111 86 91 89 96 89 89 84 84 67 80 59 73 65 65 68 74 77 65 55 67 60 63 54 77 51 69 67 70 70 55 79 69 57 57 58 60 54 53 81 69 66 75 69 63 55 71 71 63 57 66 51 63 56 49 66 66 61 46 68 70 49 66 71 54 43 54 58 61 76 67 68 50 68 65 68 53 68 63 79 53 61 69 56 60 64 68 59 75 55 64 78 66 63 64 67 50 65 67 65 57 76 76 57 71 68 67 54 78 59 71 63 49 67 59 73 58 61 65 66 71 65 60 58 76 58 63 61 65 71 61 61 45 59 50 64 55 55 51 59 63 64 64 58 61 59 57 46 58 64 51 58 55 69 54 68 55 61 65 59 47 60 58 49 57 58 60 61 66 58 61 48 59 50 58 58 67 55 58 75 63 64 61 60 64 71 69 67 71 56 57 58 58 58 71 67 67 49 65 56 67 61 73 67 64 76 60 54 58 55 77 58 60 64 73 51 56 67 48 69 68 66 42 71 67 64 65 59 75 53 66 61 67 76 67 65 82 59 70 79 75 84 86 82 79 88 101 102 122 118 152 144 149 148 171 140 122 157 138 111 115 97 112 106 91 86 84 87 92 106 80 95 86 86 102 101 108 98 108 107 117 97 96 119 90 89 76 71 87 82 70 75 90 57 69 60 80 61 80 65 59 53 82 66 77 54 67 51 48 66 74 59 56 77 70 53 59 64 63 68 84 56 59 63 68 57 61 70 67 66 59 53 64 65 75 49 51 66 74 48 57 57 55 58 60 75 65 51 60 50 66 54 66 65 66 58 75 46 74 63 65 53 74 75 75 64 70 55 66 55 64 47 44 70 69 54 68 54 49 73 51 67 65 47 66 55 60 55 67 61 75 59 67 65 64 60 70 64 74 54 50 68 63 60 60 58 70 73 69 63 49 49 73 58 75 64 48 66 60 68 68 68 77 84 70 68 54 69 64 50 75 59 57 80 78 66 71 68 66 45 74 73 57 66 69 73 80 80 81 71 67 82 97 79 88 84 88 79 97 61 89 103 103 129 137 133 118 133 144 162 180 174 195 223 216 197 228 200 243 192 197 182 127 147 157 127 109 116 128 137 126 122 109 117 126 116 122 134 123</intensities></dataPoints></scan></xrdMeasurement></xrdMeasurements>